Workbook

Sheet Company Summary W Graphs
B2: Company Overview | C2: Our company is developing an AI-driven financial projection tool that helps founders quickly produce credible, data-backed five-year forecasts. By licensing Taft’s extensive repository of early-stage startup data, we are creating an Agentic AI-based model to ask founders a series of guided questions and generate robust, investor-ready projections. This reduces human error and bias, offering a level of rigor that most first-time founders struggle to achieve. With our platform, we plan to target startups, as well as accelerators, incubators, and venture capital firms, positioning ourselves as the go-to resource for reliable, real-time financial planning.
B3: Pricing Model | C3: Hybrid tiered pricing model Basic SaaS: A cost-effective subscription tier for early-stage founders, offering core financial projection features and limited customization. Fully Customizable Service: A premium tier that provides white-glove onboarding, extensive data integrations, advanced analytics, and dedicated support—ideal for larger startups, accelerators, or corporate clients looking for in-depth forecasting capabilities.
A6: Date | B6: =Rev!M3&" "&Rev!M4 -> Year 1 Jan | C6: =Rev!N3&" "&Rev!N4 -> Year 1 Feb | D6: =Rev!O3&" "&Rev!O4 -> Year 1 Mar | E6: =Rev!P3&" "&Rev!P4 -> Year 1 Apr | F6: =Rev!Q3&" "&Rev!Q4 -> Year 1 May | G6: =Rev!R3&" "&Rev!R4 -> Year 1 Jun | H6: =Rev!S3&" "&Rev!S4 -> Year 1 Jul | I6: =Rev!T3&" "&Rev!T4 -> Year 1 Aug | ... BI6: =Rev!BT3&" "&Rev!BT4 -> Year 5 Dec
A7: Ending Cash | B7: {='P&L'!M75:BT75} -> 617172.57 | C7: 512345.14 | D7: 407517.7 | E7: 288173.61 | F7: 168829.51 | G7: 33968.742 | H7: -97229.023 | I7: -227457.79 | J7: -361361.39 | K7: 2005361.5 | L7: 1873406.4 | M7: 1738833 | N7: 1552694.1 | O7: 1387343.6 | P7: 1207295.3 | Q7: 995125.28 | R7: 783243.08 | S7: 559631.57 | T7: 331237.69 | U7: 109072.91 | V7: -132139.9 | W7: 8630837.2 | X7: 8397789.5 | Y7: 8166599.6 | Z7: 7956205.9 | AA7: 7775902.1 | AB7: 7595158.2 | AC7: 7436229.9 | AD7: 7278614.8 | AE7: 7125230.6 | AF7: 6992147.4 | AG7: 6864273.2 | AH7: 6752650.7 | AI7: 6660548.1 | AJ7: 6588286.8 | AK7: 6554663.4 | AL7: 6530521.4 | AM7: 6573280.6 | AN7: 6664225.4 | AO7: 6788803.3 | AP7: 6957920.5 | AQ7: 7183643.3 | AR7: 7459521.4 | AS7: 7776336 | AT7: 8131156.2 | AU7: 8548310.6 | AV7: 9009812.8 | AW7: 9541652.7 | AX7: 10318233 | AY7: 11205780 | AZ7: 12197103 | BA7: 13299714 | BB7: 14517283 | BC7: 15850430 | BD7: 17309838 | BE7: 18904620 | BF7: 20631423 | BG7: 22510143 | BH7: 24541678 | BI7: 26735190
A8: Op Income | B8: {='P&L'!M36:BT36} -> -128508.33 | C8: -128508.33 | D8: -128508.33 | E8: -143025 | F8: -143025 | G8: -158541.67 | H8: -154683.67 | I8: -153825.67 | J8: -157535.5 | K8: -156917.5 | L8: -155559.5 | M8: -158190.33 | N8: -192831.25 | O8: -188381.25 | P8: -203251.25 | Q8: -235472.56 | R8: -235339 | S8: -247097.31 | T8: -251620.88 | U8: -245441.88 | V8: -235614.56 | W8: -231651.5 | X8: -227465.28 | Y8: -225674.75 | Z8: -176898.51 | AA8: -173601.01 | AB8: -174827.34 | AC8: -152571.67 | AD8: -151124.25 | AE8: -147001.21 | AF8: -126746.03 | AG8: -121570.54 | AH8: -105029.04 | AI8: -85211.115 | AJ8: -65864.569 | AK8: -26317.595 | AL8: 12872.627 | AM8: 64862.088 | AN8: 124041.99 | AO8: 165029.46 | AP8: 221556.53 | AQ8: 292406.49 | AR8: 356965.91 | AS8: 407289.02 | AT8: 454307.13 | AU8: 533275.64 | AV8: 588344.72 | AW8: 677405.54 | AX8: 1001238 | AY8: 1128610.1 | AZ8: 1255120 | BA8: 1395051.2 | BB8: 1539214.7 | BC8: 1683802.5 | BD8: 1842560.3 | BE8: 2012712.5 | BF8: 2177587.1 | BG8: 2369138.3 | BH8: 2560519 | BI8: 2763780.5
A9: Rev | B9: {=Rev!M77:BT77} -> 0 | C9: 0 | D9: 0 | E9: 0 | F9: 0 | G9: 0 | H9: 3900 | I9: 4800 | J9: 5600 | K9: 6250 | L9: 7650 | M9: 8650 | N9: 48220 | O9: 53310 | P9: 61850 | Q9: 67710 | R9: 71020 | S9: 74260 | T9: 82690 | U9: 89080 | V9: 98385 | W9: 102570 | X9: 112000 | Y9: 119035 | Z9: 206150 | AA9: 221400 | AB9: 235300 | AC9: 258270 | AD9: 282110 | AE9: 303620 | AF9: 324680 | AG9: 345160 | AH9: 371550 | AI9: 402720 | AJ9: 423040 | AK9: 463710 | AL9: 631850 | AM9: 688190 | AN9: 749940 | AO9: 793630 | AP9: 854460 | AQ9: 913230 | AR9: 1002140 | AS9: 1071340 | AT9: 1136540 | AU9: 1219230 | AV9: 1292450 | AW9: 1385660 | AX9: 1761250 | AY9: 1898870 | AZ9: 2032610 | BA9: 2180120 | BB9: 2332200 | BC9: 2485100 | BD9: 2652590 | BE9: 2832010 | BF9: 3006470 | BG9: 3208270 | BH9: 3410270 | BI9: 3624740
A10: {=A6:BI6} -> Date | B10: Year 1 Jan | C10: Year 1 Feb | D10: Year 1 Mar | E10: Year 1 Apr | F10: Year 1 May | G10: Year 1 Jun | H10: Year 1 Jul | I10: Year 1 Aug | J10: Year 1 Sep | K10: Year 1 Oct | L10: Year 1 Nov | M10: Year 1 Dec | N10: Year 2 Jan | O10: Year 2 Feb | P10: Year 2 Mar | Q10: Year 2 Apr | R10: Year 2 May | S10: Year 2 Jun | T10: Year 2 Jul | U10: Year 2 Aug | V10: Year 2 Sep | W10: Year 2 Oct | X10: Year 2 Nov | Y10: Year 2 Dec | Z10: Year 3 Jan | AA10: Year 3 Feb | AB10: Year 3 Mar | AC10: Year 3 Apr | AD10: Year 3 May | AE10: Year 3 Jun | AF10: Year 3 Jul | AG10: Year 3 Aug | AH10: Year 3 Sep | AI10: Year 3 Oct | AJ10: Year 3 Nov | AK10: Year 3 Dec | AL10: Year 4 Jan | AM10: Year 4 Feb | AN10: Year 4 Mar | AO10: Year 4 Apr | AP10: Year 4 May | AQ10: Year 4 Jun | AR10: Year 4 Jul | AS10: Year 4 Aug | AT10: Year 4 Sep | AU10: Year 4 Oct | AV10: Year 4 Nov | AW10: Year 4 Dec | AX10: Year 5 Jan | AY10: Year 5 Feb | AZ10: Year 5 Mar | BA10: Year 5 Apr | BB10: Year 5 May | BC10: Year 5 Jun | BD10: Year 5 Jul | BE10: Year 5 Aug | BF10: Year 5 Sep | BG10: Year 5 Oct | BH10: Year 5 Nov | BI10: Year 5 Dec
A12: {='P&L'!J28:J31} -> R&D | B12: {='P&L'!M28:BT31} -> 16516.667 | C12: 16516.667 | D12: 16516.667 | E12: 31033.333 | F12: 31033.333 | G12: 45550 | H12: 45550 | I12: 45550 | J12: 45550 | K12: 45550 | L12: 45550 | M12: 45550 | N12: 62049.167 | O12: 62049.167 | P12: 78090.833 | Q12: 92099.167 | R12: 92099.167 | S12: 106920.83 | T12: 119687.5 | U12: 119687.5 | V12: 119687.5 | W12: 119687.5 | X12: 119687.5 | Y12: 119687.5 | Z12: 124986.88 | AA12: 135436.88 | AB12: 149953.54 | AC12: 149953.54 | AD12: 166583.54 | AE12: 183133.54 | AF12: 183133.54 | AG12: 197650.21 | AH12: 206575.21 | AI12: 216945.21 | AJ12: 216945.21 | AK12: 216945.21 | AL12: 257719.14 | AM12: 257719.14 | AN12: 257719.14 | AO12: 257719.14 | AP12: 272235.8 | AQ12: 272235.8 | AR12: 288277.47 | AS12: 303810.8 | AT12: 318632.47 | AU12: 318632.47 | AV12: 333149.14 | AW12: 333149.14 | AX12: 348211.59 | AY12: 348211.59 | AZ12: 348211.59 | BA12: 348211.59 | BB12: 348211.59 | BC12: 348211.59 | BD12: 348211.59 | BE12: 348211.59 | BF12: 348211.59 | BG12: 348211.59 | BH12: 348211.59 | BI12: 348211.59
A13: Marketing | B13: 12750 | C13: 12750 | D13: 12750 | E13: 12750 | F13: 12750 | G13: 12750 | H13: 12750 | I13: 12750 | J13: 12750 | K13: 12750 | L13: 12750 | M13: 12750 | N13: 22525 | O13: 22525 | P13: 22525 | Q13: 22525 | R13: 22525 | S13: 22525 | T13: 22525 | U13: 22525 | V13: 22525 | W13: 22525 | X13: 22525 | Y13: 22525 | Z13: 28483.333 | AA13: 28483.333 | AB13: 28483.333 | AC13: 28483.333 | AD13: 28483.333 | AE13: 28483.333 | AF13: 28483.333 | AG13: 28483.333 | AH13: 28483.333 | AI13: 28483.333 | AJ13: 28483.333 | AK13: 28483.333 | AL13: 33775 | AM13: 33775 | AN13: 33775 | AO13: 33775 | AP13: 33775 | AQ13: 33775 | AR13: 33775 | AS13: 33775 | AT13: 33775 | AU13: 33775 | AV13: 33775 | AW13: 33775 | AX13: 38650 | AY13: 38650 | AZ13: 38650 | BA13: 38650 | BB13: 38650 | BC13: 38650 | BD13: 38650 | BE13: 38650 | BF13: 38650 | BG13: 38650 | BH13: 38650 | BI13: 38650
A14: G&A | B14: 98741.667 | C14: 98741.667 | D14: 98741.667 | E14: 98741.667 | F14: 98741.667 | G14: 98741.667 | H14: 98741.667 | I14: 98741.667 | J14: 103215 | K14: 103215 | L14: 103215 | M14: 106798.33 | N14: 131263.33 | O14: 131263.33 | P14: 138446.67 | Q14: 162338.33 | R14: 165338.33 | S14: 165338.33 | T14: 165338.33 | U14: 165338.33 | V14: 164588.33 | W14: 164588.33 | X14: 169588.33 | Y14: 174588.33 | Z14: 188720 | AA14: 188720 | AB14: 188720 | AC14: 188720 | AD14: 193720 | AE14: 193720 | AF14: 193720 | AG14: 193720 | AH14: 193720 | AI14: 193720 | AJ14: 193720 | AK14: 193720 | AL14: 250545 | AM14: 250545 | AN14: 250545 | AO14: 250545 | AP14: 237545 | AQ14: 222545 | AR14: 227545 | AS14: 227545 | AT14: 227545 | AU14: 227545 | AV14: 227545 | AW14: 227545 | AX14: 227545 | AY14: 227545 | AZ14: 227545 | BA14: 227545 | BB14: 227545 | BC14: 227545 | BD14: 227545 | BE14: 227545 | BF14: 227545 | BG14: 227545 | BH14: 227545 | BI14: 227545
A15: Sales | B15: 500 | C15: 500 | D15: 500 | E15: 500 | F15: 500 | G15: 500 | H15: 500 | I15: 500 | J15: 500 | K15: 500 | L15: 500 | M15: 500 | N15: 22312.5 | O15: 22837.5 | P15: 22863.75 | Q15: 22891.312 | R15: 22920.253 | S15: 22950.641 | T15: 22982.548 | U15: 23016.05 | V15: 23051.228 | W15: 23088.164 | X15: 23126.947 | Y15: 23167.67 | Z15: 32413.553 | AA15: 33328.927 | AB15: 33419.592 | AC15: 33514.791 | AD15: 33614.749 | AE15: 33719.705 | AF15: 33829.909 | AG15: 33945.624 | AH15: 34067.124 | AI15: 34194.698 | AJ15: 34328.652 | AK15: 34469.304 | AL15: 51713.862 | AM15: 53839.402 | AN15: 54100.747 | AO15: 54375.159 | AP15: 54663.292 | AQ15: 54965.832 | AR15: 55283.498 | AS15: 55617.048 | AT15: 55967.276 | AU15: 56335.014 | AV15: 56721.14 | AW15: 57126.572 | AX15: 66155.401 | AY15: 70168.266 | AZ15: 70815.898 | BA15: 71495.912 | BB15: 72209.926 | BC15: 72959.641 | BD15: 73746.842 | BE15: 74573.403 | BF15: 75441.292 | BG15: 76352.575 | BH15: 77309.423 | BI15: 78314.113

Sheet Investor Table
B2: Attribute | C2: Description
B3: Company Name | C3: Finsight - “Financial insight at your fingertips.”
B4: Industry | C4: Financial Technology / Artificial Intelligence
B5: Core Offering | C5: AI-driven financial forecasting tool that generates accurate, data-backed five-year projections
B6: Value Proposition | C6: Leverages proprietary early-stage data to eliminate bias and uncertainty, empowering startups and investors with objective, reliable forecasts
B7: Target Markets | C7: Early-stage startups, mid-cap companies, and large enterprises requiring scalable, tailored financial projections
B8: Revenue Model | C8: Tiered SaaS pricing: Basic self-service platform for startups and a premium, customizable solution for larger clients
B9: Growth Strategy | C9: Phased team expansion with targeted sales and marketing investments, continuous product enhancements heavy focus on RnD, and strategic market penetration

Sheet Rev
B3: Assumptions | M3: Year 1 | N3: Year 1 | O3: Year 1 | P3: Year 1 | Q3: Year 1 | R3: Year 1 | S3: Year 1 | T3: Year 1 | U3: Year 1 | V3: Year 1 | W3: Year 1 | X3: Year 1 | Y3: Year 2 | Z3: Year 2 | AA3: Year 2 | AB3: Year 2 | AC3: Year 2 | AD3: Year 2 | AE3: Year 2 | AF3: Year 2 | AG3: Year 2 | AH3: Year 2 | AI3: Year 2 | AJ3: Year 2 | AK3: Year 3 | AL3: Year 3 | AM3: Year 3 | AN3: Year 3 | AO3: Year 3 | AP3: Year 3 | AQ3: Year 3 | AR3: Year 3 | AS3: Year 3 | AT3: Year 3 | AU3: Year 3 | AV3: Year 3 | AW3: Year 4 | AX3: Year 4 | AY3: Year 4 | AZ3: Year 4 | BA3: Year 4 | BB3: Year 4 | BC3: Year 4 | BD3: Year 4 | BE3: Year 4 | BF3: Year 4 | BG3: Year 4 | BH3: Year 4 | BI3: Year 5 | BJ3: Year 5 | BK3: Year 5 | BL3: Year 5 | BM3: Year 5 | BN3: Year 5 | BO3: Year 5 | BP3: Year 5 | BQ3: Year 5 | BR3: Year 5 | BS3: Year 5 | BT3: Year 5
B4: Formulaic | M4: Jan | N4: Feb | O4: Mar | P4: Apr | Q4: May | R4: Jun | S4: Jul | T4: Aug | U4: Sep | V4: Oct | W4: Nov | X4: Dec | Y4: Jan | Z4: Feb | AA4: Mar | AB4: Apr | AC4: May | AD4: Jun | AE4: Jul | AF4: Aug | AG4: Sep | AH4: Oct | AI4: Nov | AJ4: Dec | AK4: Jan | AL4: Feb | AM4: Mar | AN4: Apr | AO4: May | AP4: Jun | AQ4: Jul | AR4: Aug | AS4: Sep | AT4: Oct | AU4: Nov | AV4: Dec | AW4: Jan | AX4: Feb | AY4: Mar | AZ4: Apr | BA4: May | BB4: Jun | BC4: Jul | BD4: Aug | BE4: Sep | BF4: Oct | BG4: Nov | BH4: Dec | BI4: Jan | BJ4: Feb | BK4: Mar | BL4: Apr | BM4: May | BN4: Jun | BO4: Jul | BP4: Aug | BQ4: Sep | BR4: Oct | BS4: Nov | BT4: Dec
C7: Year | D7: 1 | E7: 2 | F7: 3 | G7: 4 | H7: 5 | J7: Onetime Fee | L7: New customers | M7: =SUM(M12:M18) -> 0 | N7: =SUM(N12:N18) -> 0 | O7: =SUM(O12:O18) -> 0 | P7: =SUM(P12:P18) -> 0 | Q7: =SUM(Q12:Q18) -> 0 | R7: =SUM(R12:R18) -> 0 | S7: =SUM(S12:S18) -> 6 | T7: =SUM(T12:T18) -> 6 | ... BT7: =SUM(BT12:BT18) -> 287
B8: Onetime fee | L8: Total Onetime Fee Rev | M8: =_xlfn.XLOOKUP(_xlfn.NUMBERVALUE(RIGHT(M$3,1)),$D$7:$H$7,$D$9:$H$9)*M7 -> 0 | N8: =_xlfn.XLOOKUP(_xlfn.NUMBERVALUE(RIGHT(N$3,1)),$D$7:$H$7,$D$9:$H$9)*N7 -> 0 | O8: =_xlfn.XLOOKUP(_xlfn.NUMBERVALUE(RIGHT(O$3,1)),$D$7:$H$7,$D$9:$H$9)*O7 -> 0 | P8: =_xlfn.XLOOKUP(_xlfn.NUMBERVALUE(RIGHT(P$3,1)),$D$7:$H$7,$D$9:$H$9)*P7 -> 0 | Q8: =_xlfn.XLOOKUP(_xlfn.NUMBERVALUE(RIGHT(Q$3,1)),$D$7:$H$7,$D$9:$H$9)*Q7 -> 0 | R8: =_xlfn.XLOOKUP(_xlfn.NUMBERVALUE(RIGHT(R$3,1)),$D$7:$H$7,$D$9:$H$9)*R7 -> 0 | S8: =_xlfn.XLOOKUP(_xlfn.NUMBERVALUE(RIGHT(S$3,1)),$D$7:$H$7,$D$9:$H$9)*S7 -> 3000 | T8: =_xlfn.XLOOKUP(_xlfn.NUMBERVALUE(RIGHT(T$3,1)),$D$7:$H$7,$D$9:$H$9)*T7 -> 3000 | ... BT8: =_xlfn.XLOOKUP(_xlfn.NUMBERVALUE(RIGHT(BT$3,1)),$D$7:$H$7,$D$9:$H$9)*BT7 -> 1291500
B9: 1.5 | C9: All Tiers | D9: 500 | E9: 2500 | F9: 3500 | G9: 4000 | H9: 4500
B10: Monthly Base Subscription Price
C11: Small Cap | D11: 100 | E11: 120 | F11: 140 | G11: 160 | H11: 180 | J11: Monthly Units (Customers Rounded w/o attrition)
C12: Mid Cap | D12: 199 | E12: 230 | F12: 260 | G12: 290 | H12: 320 | K12: Basic | L12: Small Cap | M12: =ROUND(M21,0) -> 0 | N12: =ROUND(N21,0) -> 0 | O12: =ROUND(O21,0) -> 0 | P12: =ROUND(P21,0) -> 0 | Q12: =ROUND(Q21,0) -> 0 | R12: =ROUND(R21,0) -> 0 | S12: =ROUND(S21,0) -> 4 | T12: =ROUND(T21,0) -> 4 | ... BT12: =ROUND(BT21,0) -> 9
C13: Large Cap | D13: 500 | E13: 550 | F13: 600 | G13: 650 | H13: 700 | L13: Mid Cap | M13: =ROUND(M22,0) -> 0 | N13: =ROUND(N22,0) -> 0 | O13: =ROUND(O22,0) -> 0 | P13: =ROUND(P22,0) -> 0 | Q13: =ROUND(Q22,0) -> 0 | R13: =ROUND(R22,0) -> 0 | S13: =ROUND(S22,0) -> 0 | T13: =ROUND(T22,0) -> 0 | ... BT13: =ROUND(BT22,0) -> 49
B14: Monthly Base Premium Price | L14: Large Cap | M14: =ROUND(M23,0) -> 0 | N14: =ROUND(N23,0) -> 0 | O14: =ROUND(O23,0) -> 0 | P14: =ROUND(P23,0) -> 0 | Q14: =ROUND(Q23,0) -> 0 | R14: =ROUND(R23,0) -> 0 | S14: =ROUND(S23,0) -> 0 | T14: =ROUND(T23,0) -> 0 | ... BT14: =ROUND(BT23,0) -> 86
B15: 0.5 | C15: {=C11:C13} -> Small Cap | D15: 250 | E15: 300 | F15: 350 | G15: 400 | H15: 450
C16: Mid Cap | D16: 450 | E16: 525 | F16: 580 | G16: 650 | H16: 750 | K16: Premium | L16: Small Cap | M16: =ROUND(M25,0) -> 0 | N16: =ROUND(N25,0) -> 0 | O16: =ROUND(O25,0) -> 0 | P16: =ROUND(P25,0) -> 0 | Q16: =ROUND(Q25,0) -> 0 | R16: =ROUND(R25,0) -> 0 | S16: =ROUND(S25,0) -> 2 | T16: =ROUND(T25,0) -> 2 | ... BT16: =ROUND(BT25,0) -> 14
C17: Large Cap | D17: 850 | E17: 900 | F17: 1150 | G17: 1200 | H17: 1400 | L17: Mid Cap | M17: =ROUND(M26,0) -> 0 | N17: =ROUND(N26,0) -> 0 | O17: =ROUND(O26,0) -> 0 | P17: =ROUND(P26,0) -> 0 | Q17: =ROUND(Q26,0) -> 0 | R17: =ROUND(R26,0) -> 0 | S17: =ROUND(S26,0) -> 0 | T17: =ROUND(T26,0) -> 0 | ... BT17: =ROUND(BT26,0) -> 57
L18: Large Cap | M18: =ROUND(M27,0) -> 0 | N18: =ROUND(N27,0) -> 0 | O18: =ROUND(O27,0) -> 0 | P18: =ROUND(P27,0) -> 0 | Q18: =ROUND(Q27,0) -> 0 | R18: =ROUND(R27,0) -> 0 | S18: =ROUND(S27,0) -> 0 | T18: =ROUND(T27,0) -> 0 | ... BT18: =ROUND(BT27,0) -> 72
B19: Monthly Base Sales Mix
C20: Small Cap | D20: 0.7 | E20: 0.4 | F20: 0.2 | G20: 0.05 | H20: 0.03 | J20: Monthly Sales | M20: {='Sales Rev'!M13:BT13} -> 4 | N20: 4.2 | O20: 4.41 | P20: 4.6305 | Q20: 4.862025 | R20: 5.1051263 | S20: 5.3603826 | T20: 5.6284017 | U20: 5.9098218 | V20: 6.2053129 | W20: 6.5155785 | X20: 6.8413574 | Y20: 16.441357 | Z20: 17.263425 | AA20: 18.126597 | AB20: 19.032926 | AC20: 19.984573 | AD20: 20.983801 | AE20: 22.032991 | AF20: 23.134641 | AG20: 24.291373 | AH20: 25.505942 | AI20: 26.781239 | AJ20: 28.120301 | AK20: 38.320301 | AL20: 40.236316 | AM20: 42.248132 | AN20: 44.360538 | AO20: 46.578565 | AP20: 48.907493 | AQ20: 51.352868 | AR20: 53.920511 | AS20: 56.616537 | AT20: 59.447364 | AU20: 62.419732 | AV20: 65.540719 | AW20: 84.140719 | AX20: 88.347754 | AY20: 92.765142 | AZ20: 97.403399 | BA20: 102.27357 | BB20: 107.38725 | BC20: 112.75661 | BD20: 118.39444 | BE20: 124.31416 | BF20: 130.52987 | BG20: 137.05636 | BH20: 143.90918 | BI20: 167.30918 | BJ20: 175.67464 | BK20: 184.45837 | BL20: 193.68129 | BM20: 203.36536 | BN20: 213.53362 | BO20: 224.21031 | BP20: 235.42082 | BQ20: 247.19186 | BR20: 259.55146 | BS20: 272.52903 | BT20: 286.15548
C21: Mid Cap | E21: 0.2 | F21: 0.3 | G21: 0.3 | H21: 0.17 | K21: Basic | L21: Small Cap | M21: 0 | N21: 0 | O21: 0 | P21: 0 | Q21: 0 | R21: 0 | S21: =S$20*_xlfn.XLOOKUP(_xlfn.NUMBERVALUE(RIGHT(S$3,1)),$D$7:$H$7,$D20:$H20) -> 3.7522678 | T21: =T$20*_xlfn.XLOOKUP(_xlfn.NUMBERVALUE(RIGHT(T$3,1)),$D$7:$H$7,$D20:$H20) -> 3.9398812 | U21: =U$20*_xlfn.XLOOKUP(_xlfn.NUMBERVALUE(RIGHT(U$3,1)),$D$7:$H$7,$D20:$H20) -> 4.1368752 | V21: =V$20*_xlfn.XLOOKUP(_xlfn.NUMBERVALUE(RIGHT(V$3,1)),$D$7:$H$7,$D20:$H20) -> 4.343719 | W21: =W$20*_xlfn.XLOOKUP(_xlfn.NUMBERVALUE(RIGHT(W$3,1)),$D$7:$H$7,$D20:$H20) -> 4.560905 | X21: =X$20*_xlfn.XLOOKUP(_xlfn.NUMBERVALUE(RIGHT(X$3,1)),$D$7:$H$7,$D20:$H20) -> 4.7889502 | Y21: =Y$20*_xlfn.XLOOKUP(_xlfn.NUMBERVALUE(RIGHT(Y$3,1)),$D$7:$H$7,$D20:$H20) -> 6.576543 | Z21: =Z$20*_xlfn.XLOOKUP(_xlfn.NUMBERVALUE(RIGHT(Z$3,1)),$D$7:$H$7,$D20:$H20) -> 6.9053701 | ... BT21: =BT$20*_xlfn.XLOOKUP(_xlfn.NUMBERVALUE(RIGHT(BT$3,1)),$D$7:$H$7,$D20:$H20) -> 8.5846644
C22: Large Cap | F22: 0.1 | G22: 0.2 | H22: 0.3 | L22: Mid Cap | M22: =M$20*_xlfn.XLOOKUP(_xlfn.NUMBERVALUE(RIGHT(M$3,1)),$D$7:$H$7,$D21:$H21) -> 0 | N22: =N$20*_xlfn.XLOOKUP(_xlfn.NUMBERVALUE(RIGHT(N$3,1)),$D$7:$H$7,$D21:$H21) -> 0 | O22: =O$20*_xlfn.XLOOKUP(_xlfn.NUMBERVALUE(RIGHT(O$3,1)),$D$7:$H$7,$D21:$H21) -> 0 | P22: =P$20*_xlfn.XLOOKUP(_xlfn.NUMBERVALUE(RIGHT(P$3,1)),$D$7:$H$7,$D21:$H21) -> 0 | Q22: =Q$20*_xlfn.XLOOKUP(_xlfn.NUMBERVALUE(RIGHT(Q$3,1)),$D$7:$H$7,$D21:$H21) -> 0 | R22: =R$20*_xlfn.XLOOKUP(_xlfn.NUMBERVALUE(RIGHT(R$3,1)),$D$7:$H$7,$D21:$H21) -> 0 | S22: =S$20*_xlfn.XLOOKUP(_xlfn.NUMBERVALUE(RIGHT(S$3,1)),$D$7:$H$7,$D21:$H21) -> 0 | T22: =T$20*_xlfn.XLOOKUP(_xlfn.NUMBERVALUE(RIGHT(T$3,1)),$D$7:$H$7,$D21:$H21) -> 0 | ... BT22: =BT$20*_xlfn.XLOOKUP(_xlfn.NUMBERVALUE(RIGHT(BT$3,1)),$D$7:$H$7,$D21:$H21) -> 48.646432
B23: Monthly Base Premium Sales Mix | L23: Large Cap | M23: =M$20*_xlfn.XLOOKUP(_xlfn.NUMBERVALUE(RIGHT(M$3,1)),$D$7:$H$7,$D22:$H22) -> 0 | N23: =N$20*_xlfn.XLOOKUP(_xlfn.NUMBERVALUE(RIGHT(N$3,1)),$D$7:$H$7,$D22:$H22) -> 0 | O23: =O$20*_xlfn.XLOOKUP(_xlfn.NUMBERVALUE(RIGHT(O$3,1)),$D$7:$H$7,$D22:$H22) -> 0 | P23: =P$20*_xlfn.XLOOKUP(_xlfn.NUMBERVALUE(RIGHT(P$3,1)),$D$7:$H$7,$D22:$H22) -> 0 | Q23: =Q$20*_xlfn.XLOOKUP(_xlfn.NUMBERVALUE(RIGHT(Q$3,1)),$D$7:$H$7,$D22:$H22) -> 0 | R23: =R$20*_xlfn.XLOOKUP(_xlfn.NUMBERVALUE(RIGHT(R$3,1)),$D$7:$H$7,$D22:$H22) -> 0 | S23: =S$20*_xlfn.XLOOKUP(_xlfn.NUMBERVALUE(RIGHT(S$3,1)),$D$7:$H$7,$D22:$H22) -> 0 | T23: =T$20*_xlfn.XLOOKUP(_xlfn.NUMBERVALUE(RIGHT(T$3,1)),$D$7:$H$7,$D22:$H22) -> 0 | ... BT23: =BT$20*_xlfn.XLOOKUP(_xlfn.NUMBERVALUE(RIGHT(BT$3,1)),$D$7:$H$7,$D22:$H22) -> 85.846644
C24: {=C20:C22} -> Small Cap | D24: 0.3 | E24: 0.25 | F24: 0.15 | G24: 0.05 | H24: 0.05
C25: Mid Cap | E25: 0.15 | F25: 0.15 | G25: 0.2 | H25: 0.2 | K25: Premium | L25: Small Cap | M25: 0 | N25: 0 | O25: 0 | P25: 0 | Q25: 0 | R25: 0 | S25: =S$20*_xlfn.XLOOKUP(_xlfn.NUMBERVALUE(RIGHT(S$3,1)),$D$7:$H$7,$D24:$H24) -> 1.6081148 | T25: =T$20*_xlfn.XLOOKUP(_xlfn.NUMBERVALUE(RIGHT(T$3,1)),$D$7:$H$7,$D24:$H24) -> 1.6885205 | U25: =U$20*_xlfn.XLOOKUP(_xlfn.NUMBERVALUE(RIGHT(U$3,1)),$D$7:$H$7,$D24:$H24) -> 1.7729465 | V25: =V$20*_xlfn.XLOOKUP(_xlfn.NUMBERVALUE(RIGHT(V$3,1)),$D$7:$H$7,$D24:$H24) -> 1.8615939 | W25: =W$20*_xlfn.XLOOKUP(_xlfn.NUMBERVALUE(RIGHT(W$3,1)),$D$7:$H$7,$D24:$H24) -> 1.9546736 | X25: =X$20*_xlfn.XLOOKUP(_xlfn.NUMBERVALUE(RIGHT(X$3,1)),$D$7:$H$7,$D24:$H24) -> 2.0524072 | Y25: =Y$20*_xlfn.XLOOKUP(_xlfn.NUMBERVALUE(RIGHT(Y$3,1)),$D$7:$H$7,$D24:$H24) -> 4.1103394 | Z25: =Z$20*_xlfn.XLOOKUP(_xlfn.NUMBERVALUE(RIGHT(Z$3,1)),$D$7:$H$7,$D24:$H24) -> 4.3158563 | ... BT25: =BT$20*_xlfn.XLOOKUP(_xlfn.NUMBERVALUE(RIGHT(BT$3,1)),$D$7:$H$7,$D24:$H24) -> 14.307774
C26: Large Cap | F26: 0.1 | G26: 0.2 | H26: 0.25 | L26: Mid Cap | M26: =M$20*_xlfn.XLOOKUP(_xlfn.NUMBERVALUE(RIGHT(M$3,1)),$D$7:$H$7,$D25:$H25) -> 0 | N26: =N$20*_xlfn.XLOOKUP(_xlfn.NUMBERVALUE(RIGHT(N$3,1)),$D$7:$H$7,$D25:$H25) -> 0 | O26: =O$20*_xlfn.XLOOKUP(_xlfn.NUMBERVALUE(RIGHT(O$3,1)),$D$7:$H$7,$D25:$H25) -> 0 | P26: =P$20*_xlfn.XLOOKUP(_xlfn.NUMBERVALUE(RIGHT(P$3,1)),$D$7:$H$7,$D25:$H25) -> 0 | Q26: =Q$20*_xlfn.XLOOKUP(_xlfn.NUMBERVALUE(RIGHT(Q$3,1)),$D$7:$H$7,$D25:$H25) -> 0 | R26: =R$20*_xlfn.XLOOKUP(_xlfn.NUMBERVALUE(RIGHT(R$3,1)),$D$7:$H$7,$D25:$H25) -> 0 | S26: =S$20*_xlfn.XLOOKUP(_xlfn.NUMBERVALUE(RIGHT(S$3,1)),$D$7:$H$7,$D25:$H25) -> 0 | T26: =T$20*_xlfn.XLOOKUP(_xlfn.NUMBERVALUE(RIGHT(T$3,1)),$D$7:$H$7,$D25:$H25) -> 0 | ... BT26: =BT$20*_xlfn.XLOOKUP(_xlfn.NUMBERVALUE(RIGHT(BT$3,1)),$D$7:$H$7,$D25:$H25) -> 57.231096
L27: Large Cap | M27: =M$20*_xlfn.XLOOKUP(_xlfn.NUMBERVALUE(RIGHT(M$3,1)),$D$7:$H$7,$D26:$H26) -> 0 | N27: =N$20*_xlfn.XLOOKUP(_xlfn.NUMBERVALUE(RIGHT(N$3,1)),$D$7:$H$7,$D26:$H26) -> 0 | O27: =O$20*_xlfn.XLOOKUP(_xlfn.NUMBERVALUE(RIGHT(O$3,1)),$D$7:$H$7,$D26:$H26) -> 0 | P27: =P$20*_xlfn.XLOOKUP(_xlfn.NUMBERVALUE(RIGHT(P$3,1)),$D$7:$H$7,$D26:$H26) -> 0 | Q27: =Q$20*_xlfn.XLOOKUP(_xlfn.NUMBERVALUE(RIGHT(Q$3,1)),$D$7:$H$7,$D26:$H26) -> 0 | R27: =R$20*_xlfn.XLOOKUP(_xlfn.NUMBERVALUE(RIGHT(R$3,1)),$D$7:$H$7,$D26:$H26) -> 0 | S27: =S$20*_xlfn.XLOOKUP(_xlfn.NUMBERVALUE(RIGHT(S$3,1)),$D$7:$H$7,$D26:$H26) -> 0 | T27: =T$20*_xlfn.XLOOKUP(_xlfn.NUMBERVALUE(RIGHT(T$3,1)),$D$7:$H$7,$D26:$H26) -> 0 | ... BT27: =BT$20*_xlfn.XLOOKUP(_xlfn.NUMBERVALUE(RIGHT(BT$3,1)),$D$7:$H$7,$D26:$H26) -> 71.53887
J29: Total Customers w/o Attrition
K30: Basic | L30: Small Cap | M30: =M12 -> 0 | N30: =M30+N12 -> 0 | O30: =N30+O12 -> 0 | P30: =O30+P12 -> 0 | Q30: =P30+Q12 -> 0 | R30: =Q30+R12 -> 0 | S30: =R30+S12 -> 4 | T30: =S30+T12 -> 8 | U30: =T30+U12 -> 12 | ... BT30: =BS30+BT12 -> 399
B31: Cash Collections | C31: Month 1 | D31: 0.95 | L31: Mid Cap | M31: =M13 -> 0 | N31: =M31+N13 -> 0 | O31: =N31+O13 -> 0 | P31: =O31+P13 -> 0 | Q31: =P31+Q13 -> 0 | R31: =Q31+R13 -> 0 | S31: =R31+S13 -> 0 | T31: =S31+T13 -> 0 | U31: =T31+U13 -> 0 | ... BT31: =BS31+BT13 -> 1089
C32: Month 2 | D32: 0.04 | L32: Large Cap | M32: =M14 -> 0 | N32: =M32+N14 -> 0 | O32: =N32+O14 -> 0 | P32: =O32+P14 -> 0 | Q32: =P32+Q14 -> 0 | R32: =Q32+R14 -> 0 | S32: =R32+S14 -> 0 | T32: =S32+T14 -> 0 | U32: =T32+U14 -> 0 | ... BT32: =BS32+BT14 -> 1128
C33: Month 3 | D33: 0.01
K34: Premium | L34: Small Cap | M34: =M16 -> 0 | N34: =M34+N16 -> 0 | O34: =N34+O16 -> 0 | P34: =O34+P16 -> 0 | Q34: =P34+Q16 -> 0 | R34: =Q34+R16 -> 0 | S34: =R34+S16 -> 2 | T34: =S34+T16 -> 4 | U34: =T34+U16 -> 6 | ... BT34: =BS34+BT16 -> 369
D35: Year | L35: Mid Cap | M35: =M17 -> 0 | N35: =M35+N17 -> 0 | O35: =N35+O17 -> 0 | P35: =O35+P17 -> 0 | Q35: =P35+Q17 -> 0 | R35: =Q35+R17 -> 0 | S35: =R35+S17 -> 0 | T35: =S35+T17 -> 0 | U35: =T35+U17 -> 0 | ... BT35: =BS35+BT17 -> 931
B36: Users | C36: Percentage | D36: 0-1 | E36: 1-2 | F36: 2-3 | G36: 3-4 | H36: 4-5 | L36: Large Cap | M36: =M18 -> 0 | N36: =M36+N18 -> 0 | O36: =N36+O18 -> 0 | P36: =O36+P18 -> 0 | Q36: =P36+Q18 -> 0 | R36: =Q36+R18 -> 0 | S36: =R36+S18 -> 0 | T36: =S36+T18 -> 0 | U36: =T36+U18 -> 0 | ... BT36: =BS36+BT18 -> 995
B37: Abandon Rate | D37: 0.01 | E37: 0.15 | F37: 0.15 | G37: 0.15 | H37: 0.15
B38: Attrition rate | D38: 0.1 | E38: 0.2 | F38: 0.2 | G38: 0.2 | H38: 0.2
J39: Attrition Units
B40: Starting Customers | K40: Basic | L40: Small Cap | N40: =(M30*(_xlfn.XLOOKUP(_xlfn.NUMBERVALUE(RIGHT(N$3,1)),$D$7:$H$7,$D$38:$H$38))) -> 0 | O40: =(N30*(_xlfn.XLOOKUP(_xlfn.NUMBERVALUE(RIGHT(O$3,1)),$D$7:$H$7,$D$38:$H$38))) -> 0 | P40: =(O30*(_xlfn.XLOOKUP(_xlfn.NUMBERVALUE(RIGHT(P$3,1)),$D$7:$H$7,$D$38:$H$38))) -> 0 | Q40: =(P30*(_xlfn.XLOOKUP(_xlfn.NUMBERVALUE(RIGHT(Q$3,1)),$D$7:$H$7,$D$38:$H$38))) -> 0 | R40: =(Q30*(_xlfn.XLOOKUP(_xlfn.NUMBERVALUE(RIGHT(R$3,1)),$D$7:$H$7,$D$38:$H$38))) -> 0 | S40: =(R30*(_xlfn.XLOOKUP(_xlfn.NUMBERVALUE(RIGHT(S$3,1)),$D$7:$H$7,$D$38:$H$38))) -> 0 | T40: =(S30*(_xlfn.XLOOKUP(_xlfn.NUMBERVALUE(RIGHT(T$3,1)),$D$7:$H$7,$D$38:$H$38))) -> 0.4 | U40: =(T30*(_xlfn.XLOOKUP(_xlfn.NUMBERVALUE(RIGHT(U$3,1)),$D$7:$H$7,$D$38:$H$38))) -> 0.8 | ... BT40: =(BS30*(_xlfn.XLOOKUP(_xlfn.NUMBERVALUE(RIGHT(BT$3,1)),$D$7:$H$7,$D$38:$H$38))) -> 78
B41: Basic | C41: Small Cap | D41: 10 | L41: Mid Cap | N41: =(M31*(_xlfn.XLOOKUP(_xlfn.NUMBERVALUE(RIGHT(N$3,1)),$D$7:$H$7,$D$38:$H$38))) -> 0 | O41: =(N31*(_xlfn.XLOOKUP(_xlfn.NUMBERVALUE(RIGHT(O$3,1)),$D$7:$H$7,$D$38:$H$38))) -> 0 | P41: =(O31*(_xlfn.XLOOKUP(_xlfn.NUMBERVALUE(RIGHT(P$3,1)),$D$7:$H$7,$D$38:$H$38))) -> 0 | Q41: =(P31*(_xlfn.XLOOKUP(_xlfn.NUMBERVALUE(RIGHT(Q$3,1)),$D$7:$H$7,$D$38:$H$38))) -> 0 | R41: =(Q31*(_xlfn.XLOOKUP(_xlfn.NUMBERVALUE(RIGHT(R$3,1)),$D$7:$H$7,$D$38:$H$38))) -> 0 | S41: =(R31*(_xlfn.XLOOKUP(_xlfn.NUMBERVALUE(RIGHT(S$3,1)),$D$7:$H$7,$D$38:$H$38))) -> 0 | T41: =(S31*(_xlfn.XLOOKUP(_xlfn.NUMBERVALUE(RIGHT(T$3,1)),$D$7:$H$7,$D$38:$H$38))) -> 0 | U41: =(T31*(_xlfn.XLOOKUP(_xlfn.NUMBERVALUE(RIGHT(U$3,1)),$D$7:$H$7,$D$38:$H$38))) -> 0 | ... BT41: =(BS31*(_xlfn.XLOOKUP(_xlfn.NUMBERVALUE(RIGHT(BT$3,1)),$D$7:$H$7,$D$38:$H$38))) -> 208
C42: Mid Cap | D42: 10 | L42: Large Cap | N42: =(M32*(_xlfn.XLOOKUP(_xlfn.NUMBERVALUE(RIGHT(N$3,1)),$D$7:$H$7,$D$38:$H$38))) -> 0 | O42: =(N32*(_xlfn.XLOOKUP(_xlfn.NUMBERVALUE(RIGHT(O$3,1)),$D$7:$H$7,$D$38:$H$38))) -> 0 | P42: =(O32*(_xlfn.XLOOKUP(_xlfn.NUMBERVALUE(RIGHT(P$3,1)),$D$7:$H$7,$D$38:$H$38))) -> 0 | Q42: =(P32*(_xlfn.XLOOKUP(_xlfn.NUMBERVALUE(RIGHT(Q$3,1)),$D$7:$H$7,$D$38:$H$38))) -> 0 | R42: =(Q32*(_xlfn.XLOOKUP(_xlfn.NUMBERVALUE(RIGHT(R$3,1)),$D$7:$H$7,$D$38:$H$38))) -> 0 | S42: =(R32*(_xlfn.XLOOKUP(_xlfn.NUMBERVALUE(RIGHT(S$3,1)),$D$7:$H$7,$D$38:$H$38))) -> 0 | T42: =(S32*(_xlfn.XLOOKUP(_xlfn.NUMBERVALUE(RIGHT(T$3,1)),$D$7:$H$7,$D$38:$H$38))) -> 0 | U42: =(T32*(_xlfn.XLOOKUP(_xlfn.NUMBERVALUE(RIGHT(U$3,1)),$D$7:$H$7,$D$38:$H$38))) -> 0 | ... BT42: =(BS32*(_xlfn.XLOOKUP(_xlfn.NUMBERVALUE(RIGHT(BT$3,1)),$D$7:$H$7,$D$38:$H$38))) -> 208.4
C43: Large Cap | D43: 5
B44: Premium | K44: Premium | L44: Small Cap | N44: =(M34*(_xlfn.XLOOKUP(_xlfn.NUMBERVALUE(RIGHT(N$3,1)),$D$7:$H$7,$D$38:$H$38))) -> 0 | O44: =(N34*(_xlfn.XLOOKUP(_xlfn.NUMBERVALUE(RIGHT(O$3,1)),$D$7:$H$7,$D$38:$H$38))) -> 0 | P44: =(O34*(_xlfn.XLOOKUP(_xlfn.NUMBERVALUE(RIGHT(P$3,1)),$D$7:$H$7,$D$38:$H$38))) -> 0 | Q44: =(P34*(_xlfn.XLOOKUP(_xlfn.NUMBERVALUE(RIGHT(Q$3,1)),$D$7:$H$7,$D$38:$H$38))) -> 0 | R44: =(Q34*(_xlfn.XLOOKUP(_xlfn.NUMBERVALUE(RIGHT(R$3,1)),$D$7:$H$7,$D$38:$H$38))) -> 0 | S44: =(R34*(_xlfn.XLOOKUP(_xlfn.NUMBERVALUE(RIGHT(S$3,1)),$D$7:$H$7,$D$38:$H$38))) -> 0 | T44: =(S34*(_xlfn.XLOOKUP(_xlfn.NUMBERVALUE(RIGHT(T$3,1)),$D$7:$H$7,$D$38:$H$38))) -> 0.2 | U44: =(T34*(_xlfn.XLOOKUP(_xlfn.NUMBERVALUE(RIGHT(U$3,1)),$D$7:$H$7,$D$38:$H$38))) -> 0.4 | ... BT44: =(BS34*(_xlfn.XLOOKUP(_xlfn.NUMBERVALUE(RIGHT(BT$3,1)),$D$7:$H$7,$D$38:$H$38))) -> 71
C45: Small Cap | D45: 10 | L45: Mid Cap | N45: =(M35*(_xlfn.XLOOKUP(_xlfn.NUMBERVALUE(RIGHT(N$3,1)),$D$7:$H$7,$D$38:$H$38))) -> 0 | O45: =(N35*(_xlfn.XLOOKUP(_xlfn.NUMBERVALUE(RIGHT(O$3,1)),$D$7:$H$7,$D$38:$H$38))) -> 0 | P45: =(O35*(_xlfn.XLOOKUP(_xlfn.NUMBERVALUE(RIGHT(P$3,1)),$D$7:$H$7,$D$38:$H$38))) -> 0 | Q45: =(P35*(_xlfn.XLOOKUP(_xlfn.NUMBERVALUE(RIGHT(Q$3,1)),$D$7:$H$7,$D$38:$H$38))) -> 0 | R45: =(Q35*(_xlfn.XLOOKUP(_xlfn.NUMBERVALUE(RIGHT(R$3,1)),$D$7:$H$7,$D$38:$H$38))) -> 0 | S45: =(R35*(_xlfn.XLOOKUP(_xlfn.NUMBERVALUE(RIGHT(S$3,1)),$D$7:$H$7,$D$38:$H$38))) -> 0 | T45: =(S35*(_xlfn.XLOOKUP(_xlfn.NUMBERVALUE(RIGHT(T$3,1)),$D$7:$H$7,$D$38:$H$38))) -> 0 | U45: =(T35*(_xlfn.XLOOKUP(_xlfn.NUMBERVALUE(RIGHT(U$3,1)),$D$7:$H$7,$D$38:$H$38))) -> 0 | ... BT45: =(BS35*(_xlfn.XLOOKUP(_xlfn.NUMBERVALUE(RIGHT(BT$3,1)),$D$7:$H$7,$D$38:$H$38))) -> 174.8
...

Sheet Sales Rev
A1: Sales Per Person
B2: Role | C2: Year 1 | D2: Year 2 | E2: Year 3 | F2: Year 4 | G2: Year 5 | H2: Monthly Learning Curve | M2: Year 1 | N2: Year 1 | O2: Year 1 | P2: Year 1 | Q2: Year 1 | R2: Year 1 | S2: Year 1 | T2: Year 1 | U2: Year 1 | V2: Year 1 | W2: Year 1 | X2: Year 1 | Y2: Year 2 | Z2: Year 2 | AA2: Year 2 | AB2: Year 2 | AC2: Year 2 | AD2: Year 2 | AE2: Year 2 | AF2: Year 2 | AG2: Year 2 | AH2: Year 2 | AI2: Year 2 | AJ2: Year 2 | AK2: Year 3 | AL2: Year 3 | AM2: Year 3 | AN2: Year 3 | AO2: Year 3 | AP2: Year 3 | AQ2: Year 3 | AR2: Year 3 | AS2: Year 3 | AT2: Year 3 | AU2: Year 3 | AV2: Year 3 | AW2: Year 4 | AX2: Year 4 | AY2: Year 4 | AZ2: Year 4 | BA2: Year 4 | BB2: Year 4 | BC2: Year 4 | BD2: Year 4 | BE2: Year 4 | BF2: Year 4 | BG2: Year 4 | BH2: Year 4 | BI2: Year 5 | BJ2: Year 5 | BK2: Year 5 | BL2: Year 5 | BM2: Year 5 | BN2: Year 5 | BO2: Year 5 | BP2: Year 5 | BQ2: Year 5 | BR2: Year 5 | BS2: Year 5 | BT2: Year 5
B3: Customer Success Manager | F3: 1.2 | G3: 1.5 | H3: 1.05 | J3: Unrounded Sales | M3: Jan | N3: Feb | O3: Mar | P3: Apr | Q3: May | R3: Jun | S3: Jul | T3: Aug | U3: Sep | V3: Oct | W3: Nov | X3: Dec | Y3: Jan | Z3: Feb | AA3: Mar | AB3: Apr | AC3: May | AD3: Jun | AE3: Jul | AF3: Aug | AG3: Sep | AH3: Oct | AI3: Nov | AJ3: Dec | AK3: Jan | AL3: Feb | AM3: Mar | AN3: Apr | AO3: May | AP3: Jun | AQ3: Jul | AR3: Aug | AS3: Sep | AT3: Oct | AU3: Nov | AV3: Dec | AW3: Jan | AX3: Feb | AY3: Mar | AZ3: Apr | BA3: May | BB3: Jun | BC3: Jul | BD3: Aug | BE3: Sep | BF3: Oct | BG3: Nov | BH3: Dec | BI3: Jan | BJ3: Feb | BK3: Mar | BL3: Apr | BM3: May | BN3: Jun | BO3: Jul | BP3: Aug | BQ3: Sep | BR3: Oct | BS3: Nov | BT3: Dec
B4: Founder | C4: 4 | D4: 3.6 | E4: 2.8 | F4: 2 | G4: 1.2 | H4: 1.05 | K4: Customer Success Manager | M4: =IF(M$3=$M$3,_xlfn.XLOOKUP(M$2,$C$2:$G$2,$C3:$G3)+L4,L4*$H3) -> 0 | N4: =IF(N$3=$M$3,_xlfn.XLOOKUP(N$2,$C$2:$G$2,$C3:$G3)+M4,M4*$H3) -> 0 | O4: =IF(O$3=$M$3,_xlfn.XLOOKUP(O$2,$C$2:$G$2,$C3:$G3)+N4,N4*$H3) -> 0 | P4: =IF(P$3=$M$3,_xlfn.XLOOKUP(P$2,$C$2:$G$2,$C3:$G3)+O4,O4*$H3) -> 0 | Q4: =IF(Q$3=$M$3,_xlfn.XLOOKUP(Q$2,$C$2:$G$2,$C3:$G3)+P4,P4*$H3) -> 0 | R4: =IF(R$3=$M$3,_xlfn.XLOOKUP(R$2,$C$2:$G$2,$C3:$G3)+Q4,Q4*$H3) -> 0 | S4: =IF(S$3=$M$3,_xlfn.XLOOKUP(S$2,$C$2:$G$2,$C3:$G3)+R4,R4*$H3) -> 0 | T4: =IF(T$3=$M$3,_xlfn.XLOOKUP(T$2,$C$2:$G$2,$C3:$G3)+S4,S4*$H3) -> 0 | ... BT4: =IF(BT$3=$M$3,_xlfn.XLOOKUP(BT$2,$C$2:$G$2,$C3:$G3)+BS4,BS4*$H3) -> 6.0758219
B5: Regional Sales Manager | F5: 3 | G5: 3.2 | H5: 1.05 | K5: Founder | M5: =IF(M$3=$M$3,_xlfn.XLOOKUP(M$2,$C$2:$G$2,$C4:$G4)+L5,L5*$H4) -> 4 | N5: =IF(N$3=$M$3,_xlfn.XLOOKUP(N$2,$C$2:$G$2,$C4:$G4)+M5,M5*$H4) -> 4.2 | O5: =IF(O$3=$M$3,_xlfn.XLOOKUP(O$2,$C$2:$G$2,$C4:$G4)+N5,N5*$H4) -> 4.41 | P5: =IF(P$3=$M$3,_xlfn.XLOOKUP(P$2,$C$2:$G$2,$C4:$G4)+O5,O5*$H4) -> 4.6305 | Q5: =IF(Q$3=$M$3,_xlfn.XLOOKUP(Q$2,$C$2:$G$2,$C4:$G4)+P5,P5*$H4) -> 4.862025 | R5: =IF(R$3=$M$3,_xlfn.XLOOKUP(R$2,$C$2:$G$2,$C4:$G4)+Q5,Q5*$H4) -> 5.1051263 | S5: =IF(S$3=$M$3,_xlfn.XLOOKUP(S$2,$C$2:$G$2,$C4:$G4)+R5,R5*$H4) -> 5.3603826 | T5: =IF(T$3=$M$3,_xlfn.XLOOKUP(T$2,$C$2:$G$2,$C4:$G4)+S5,S5*$H4) -> 5.6284017 | ... BT5: =IF(BT$3=$M$3,_xlfn.XLOOKUP(BT$2,$C$2:$G$2,$C4:$G4)+BS5,BS5*$H4) -> 111.26012
B6: Sales Rep | D6: 2 | E6: 2.6 | F6: 3 | G6: 3.2 | H6: 1.05 | K6: Regional Sales Manager | M6: =IF(M$3=$M$3,_xlfn.XLOOKUP(M$2,$C$2:$G$2,$C5:$G5)+L6,L6*$H5) -> 0 | N6: =IF(N$3=$M$3,_xlfn.XLOOKUP(N$2,$C$2:$G$2,$C5:$G5)+M6,M6*$H5) -> 0 | O6: =IF(O$3=$M$3,_xlfn.XLOOKUP(O$2,$C$2:$G$2,$C5:$G5)+N6,N6*$H5) -> 0 | P6: =IF(P$3=$M$3,_xlfn.XLOOKUP(P$2,$C$2:$G$2,$C5:$G5)+O6,O6*$H5) -> 0 | Q6: =IF(Q$3=$M$3,_xlfn.XLOOKUP(Q$2,$C$2:$G$2,$C5:$G5)+P6,P6*$H5) -> 0 | R6: =IF(R$3=$M$3,_xlfn.XLOOKUP(R$2,$C$2:$G$2,$C5:$G5)+Q6,Q6*$H5) -> 0 | S6: =IF(S$3=$M$3,_xlfn.XLOOKUP(S$2,$C$2:$G$2,$C5:$G5)+R6,R6*$H5) -> 0 | T6: =IF(T$3=$M$3,_xlfn.XLOOKUP(T$2,$C$2:$G$2,$C5:$G5)+S6,S6*$H5) -> 0 | ... BT6: =IF(BT$3=$M$3,_xlfn.XLOOKUP(BT$2,$C$2:$G$2,$C5:$G5)+BS6,BS6*$H5) -> 14.248868
B7: Additional Sales Rep | G7: 4 | H7: 1.05 | K7: Sales Rep | M7: =IF(M$3=$M$3,_xlfn.XLOOKUP(M$2,$C$2:$G$2,$C6:$G6)+L7,L7*$H6) -> 0 | N7: =IF(N$3=$M$3,_xlfn.XLOOKUP(N$2,$C$2:$G$2,$C6:$G6)+M7,M7*$H6) -> 0 | O7: =IF(O$3=$M$3,_xlfn.XLOOKUP(O$2,$C$2:$G$2,$C6:$G6)+N7,N7*$H6) -> 0 | P7: =IF(P$3=$M$3,_xlfn.XLOOKUP(P$2,$C$2:$G$2,$C6:$G6)+O7,O7*$H6) -> 0 | Q7: =IF(Q$3=$M$3,_xlfn.XLOOKUP(Q$2,$C$2:$G$2,$C6:$G6)+P7,P7*$H6) -> 0 | R7: =IF(R$3=$M$3,_xlfn.XLOOKUP(R$2,$C$2:$G$2,$C6:$G6)+Q7,Q7*$H6) -> 0 | S7: =IF(S$3=$M$3,_xlfn.XLOOKUP(S$2,$C$2:$G$2,$C6:$G6)+R7,R7*$H6) -> 0 | T7: =IF(T$3=$M$3,_xlfn.XLOOKUP(T$2,$C$2:$G$2,$C6:$G6)+S7,S7*$H6) -> 0 | ... BT7: =IF(BT$3=$M$3,_xlfn.XLOOKUP(BT$2,$C$2:$G$2,$C6:$G6)+BS7,BS7*$H6) -> 44.371459
B8: Sales Rep | D8: 2 | E8: 2.6 | F8: 3 | G8: 3.2 | H8: 1.05 | K8: Additional Sales Rep | M8: =IF(M$3=$M$3,_xlfn.XLOOKUP(M$2,$C$2:$G$2,$C7:$G7)+L8,L8*$H7) -> 0 | N8: =IF(N$3=$M$3,_xlfn.XLOOKUP(N$2,$C$2:$G$2,$C7:$G7)+M8,M8*$H7) -> 0 | O8: =IF(O$3=$M$3,_xlfn.XLOOKUP(O$2,$C$2:$G$2,$C7:$G7)+N8,N8*$H7) -> 0 | P8: =IF(P$3=$M$3,_xlfn.XLOOKUP(P$2,$C$2:$G$2,$C7:$G7)+O8,O8*$H7) -> 0 | Q8: =IF(Q$3=$M$3,_xlfn.XLOOKUP(Q$2,$C$2:$G$2,$C7:$G7)+P8,P8*$H7) -> 0 | R8: =IF(R$3=$M$3,_xlfn.XLOOKUP(R$2,$C$2:$G$2,$C7:$G7)+Q8,Q8*$H7) -> 0 | S8: =IF(S$3=$M$3,_xlfn.XLOOKUP(S$2,$C$2:$G$2,$C7:$G7)+R8,R8*$H7) -> 0 | T8: =IF(T$3=$M$3,_xlfn.XLOOKUP(T$2,$C$2:$G$2,$C7:$G7)+S8,S8*$H7) -> 0 | ... BT8: =IF(BT$3=$M$3,_xlfn.XLOOKUP(BT$2,$C$2:$G$2,$C7:$G7)+BS8,BS8*$H7) -> 6.8413574
B9: Sales VP | D9: 2 | E9: 2.2 | F9: 2.4 | G9: 2.6 | H9: 1.05 | K9: Sales Rep | M9: =IF(M$3=$M$3,_xlfn.XLOOKUP(M$2,$C$2:$G$2,$C8:$G8)+L9,L9*$H8) -> 0 | N9: =IF(N$3=$M$3,_xlfn.XLOOKUP(N$2,$C$2:$G$2,$C8:$G8)+M9,M9*$H8) -> 0 | O9: =IF(O$3=$M$3,_xlfn.XLOOKUP(O$2,$C$2:$G$2,$C8:$G8)+N9,N9*$H8) -> 0 | P9: =IF(P$3=$M$3,_xlfn.XLOOKUP(P$2,$C$2:$G$2,$C8:$G8)+O9,O9*$H8) -> 0 | Q9: =IF(Q$3=$M$3,_xlfn.XLOOKUP(Q$2,$C$2:$G$2,$C8:$G8)+P9,P9*$H8) -> 0 | R9: =IF(R$3=$M$3,_xlfn.XLOOKUP(R$2,$C$2:$G$2,$C8:$G8)+Q9,Q9*$H8) -> 0 | S9: =IF(S$3=$M$3,_xlfn.XLOOKUP(S$2,$C$2:$G$2,$C8:$G8)+R9,R9*$H8) -> 0 | T9: =IF(T$3=$M$3,_xlfn.XLOOKUP(T$2,$C$2:$G$2,$C8:$G8)+S9,S9*$H8) -> 0 | ... BT9: =IF(BT$3=$M$3,_xlfn.XLOOKUP(BT$2,$C$2:$G$2,$C8:$G8)+BS9,BS9*$H8) -> 44.371459
B10: Senior Sales Rep | F10: 4 | G10: 4.5 | H10: 1.05 | K10: Sales VP | M10: =IF(M$3=$M$3,_xlfn.XLOOKUP(M$2,$C$2:$G$2,$C9:$G9)+L10,L10*$H9) -> 0 | N10: =IF(N$3=$M$3,_xlfn.XLOOKUP(N$2,$C$2:$G$2,$C9:$G9)+M10,M10*$H9) -> 0 | O10: =IF(O$3=$M$3,_xlfn.XLOOKUP(O$2,$C$2:$G$2,$C9:$G9)+N10,N10*$H9) -> 0 | P10: =IF(P$3=$M$3,_xlfn.XLOOKUP(P$2,$C$2:$G$2,$C9:$G9)+O10,O10*$H9) -> 0 | Q10: =IF(Q$3=$M$3,_xlfn.XLOOKUP(Q$2,$C$2:$G$2,$C9:$G9)+P10,P10*$H9) -> 0 | R10: =IF(R$3=$M$3,_xlfn.XLOOKUP(R$2,$C$2:$G$2,$C9:$G9)+Q10,Q10*$H9) -> 0 | S10: =IF(S$3=$M$3,_xlfn.XLOOKUP(S$2,$C$2:$G$2,$C9:$G9)+R10,R10*$H9) -> 0 | T10: =IF(T$3=$M$3,_xlfn.XLOOKUP(T$2,$C$2:$G$2,$C9:$G9)+S10,S10*$H9) -> 0 | ... BT10: =IF(BT$3=$M$3,_xlfn.XLOOKUP(BT$2,$C$2:$G$2,$C9:$G9)+BS10,BS10*$H9) -> 39.588823
K11: Senior Sales Rep | M11: =IF(M$3=$M$3,_xlfn.XLOOKUP(M$2,$C$2:$G$2,$C10:$G10)+L11,L11*$H10) -> 0 | N11: =IF(N$3=$M$3,_xlfn.XLOOKUP(N$2,$C$2:$G$2,$C10:$G10)+M11,M11*$H10) -> 0 | O11: =IF(O$3=$M$3,_xlfn.XLOOKUP(O$2,$C$2:$G$2,$C10:$G10)+N11,N11*$H10) -> 0 | P11: =IF(P$3=$M$3,_xlfn.XLOOKUP(P$2,$C$2:$G$2,$C10:$G10)+O11,O11*$H10) -> 0 | Q11: =IF(Q$3=$M$3,_xlfn.XLOOKUP(Q$2,$C$2:$G$2,$C10:$G10)+P11,P11*$H10) -> 0 | R11: =IF(R$3=$M$3,_xlfn.XLOOKUP(R$2,$C$2:$G$2,$C10:$G10)+Q11,Q11*$H10) -> 0 | S11: =IF(S$3=$M$3,_xlfn.XLOOKUP(S$2,$C$2:$G$2,$C10:$G10)+R11,R11*$H10) -> 0 | T11: =IF(T$3=$M$3,_xlfn.XLOOKUP(T$2,$C$2:$G$2,$C10:$G10)+S11,S11*$H10) -> 0 | ... BT11: =IF(BT$3=$M$3,_xlfn.XLOOKUP(BT$2,$C$2:$G$2,$C10:$G10)+BS11,BS11*$H10) -> 19.39757
B12: Beginning Sales | C12: Starting Year | J12: Comissions
B13: Customer Success Manager | C13: ='Sales & Marketing'!D19 -> 4 | K13: Total Monthly Sales | M13: =SUM(M4:M11) -> 4 | N13: =SUM(N4:N11) -> 4.2 | O13: =SUM(O4:O11) -> 4.41 | P13: =SUM(P4:P11) -> 4.6305 | Q13: =SUM(Q4:Q11) -> 4.862025 | R13: =SUM(R4:R11) -> 5.1051263 | S13: =SUM(S4:S11) -> 5.3603826 | T13: =SUM(T4:T11) -> 5.6284017 | ... BT13: =SUM(BT4:BT11) -> 286.15548
B14: Founder | C14: 1
B15: Regional Sales Manager | C15: ='Sales & Marketing'!D18 -> 4 | K15: Customer Success Manager | M15: {=_xlfn.XLOOKUP(M$2,_xlfn.ANCHORARRAY($C$21),$C$24:$G$24)*M4*$C$23} -> 0 | N15: {=_xlfn.XLOOKUP(N$2,_xlfn.ANCHORARRAY($C$21),$C$24:$G$24)*N4*$C$23} -> 0 | O15: {=_xlfn.XLOOKUP(O$2,_xlfn.ANCHORARRAY($C$21),$C$24:$G$24)*O4*$C$23} -> 0 | P15: {=_xlfn.XLOOKUP(P$2,_xlfn.ANCHORARRAY($C$21),$C$24:$G$24)*P4*$C$23} -> 0 | Q15: {=_xlfn.XLOOKUP(Q$2,_xlfn.ANCHORARRAY($C$21),$C$24:$G$24)*Q4*$C$23} -> 0 | R15: {=_xlfn.XLOOKUP(R$2,_xlfn.ANCHORARRAY($C$21),$C$24:$G$24)*R4*$C$23} -> 0 | S15: {=_xlfn.XLOOKUP(S$2,_xlfn.ANCHORARRAY($C$21),$C$24:$G$24)*S4*$C$23} -> 0 | T15: {=_xlfn.XLOOKUP(T$2,_xlfn.ANCHORARRAY($C$21),$C$24:$G$24)*T4*$C$23} -> 0 | ... BT15: {=_xlfn.XLOOKUP(BT$2,_xlfn.ANCHORARRAY($C$21),$C$24:$G$24)*BT4*$C$23} -> 769.60411
B16: Sales Rep | C16: 2 | K16: Founder
B17: Additional Sales Rep | C17: 5 | K17: Regional Sales Manager | M17: {=_xlfn.XLOOKUP(M$2,_xlfn.ANCHORARRAY($C$21),$C$24:$G$24)*M6*$C$23} -> 0 | N17: {=_xlfn.XLOOKUP(N$2,_xlfn.ANCHORARRAY($C$21),$C$24:$G$24)*N6*$C$23} -> 0 | O17: {=_xlfn.XLOOKUP(O$2,_xlfn.ANCHORARRAY($C$21),$C$24:$G$24)*O6*$C$23} -> 0 | P17: {=_xlfn.XLOOKUP(P$2,_xlfn.ANCHORARRAY($C$21),$C$24:$G$24)*P6*$C$23} -> 0 | Q17: {=_xlfn.XLOOKUP(Q$2,_xlfn.ANCHORARRAY($C$21),$C$24:$G$24)*Q6*$C$23} -> 0 | R17: {=_xlfn.XLOOKUP(R$2,_xlfn.ANCHORARRAY($C$21),$C$24:$G$24)*R6*$C$23} -> 0 | S17: {=_xlfn.XLOOKUP(S$2,_xlfn.ANCHORARRAY($C$21),$C$24:$G$24)*S6*$C$23} -> 0 | T17: {=_xlfn.XLOOKUP(T$2,_xlfn.ANCHORARRAY($C$21),$C$24:$G$24)*T6*$C$23} -> 0 | ... BT17: {=_xlfn.XLOOKUP(BT$2,_xlfn.ANCHORARRAY($C$21),$C$24:$G$24)*BT6*$C$23} -> 1804.8566
B18: Sales Rep | C18: ='Sales & Marketing'!D14 -> 2 | K18: Sales Rep | M18: {=_xlfn.XLOOKUP(M$2,_xlfn.ANCHORARRAY($C$21),$C$24:$G$24)*M7*$C$23} -> 0 | N18: {=_xlfn.XLOOKUP(N$2,_xlfn.ANCHORARRAY($C$21),$C$24:$G$24)*N7*$C$23} -> 0 | O18: {=_xlfn.XLOOKUP(O$2,_xlfn.ANCHORARRAY($C$21),$C$24:$G$24)*O7*$C$23} -> 0 | P18: {=_xlfn.XLOOKUP(P$2,_xlfn.ANCHORARRAY($C$21),$C$24:$G$24)*P7*$C$23} -> 0 | Q18: {=_xlfn.XLOOKUP(Q$2,_xlfn.ANCHORARRAY($C$21),$C$24:$G$24)*Q7*$C$23} -> 0 | R18: {=_xlfn.XLOOKUP(R$2,_xlfn.ANCHORARRAY($C$21),$C$24:$G$24)*R7*$C$23} -> 0 | S18: {=_xlfn.XLOOKUP(S$2,_xlfn.ANCHORARRAY($C$21),$C$24:$G$24)*S7*$C$23} -> 0 | T18: {=_xlfn.XLOOKUP(T$2,_xlfn.ANCHORARRAY($C$21),$C$24:$G$24)*T7*$C$23} -> 0 | ... BT18: {=_xlfn.XLOOKUP(BT$2,_xlfn.ANCHORARRAY($C$21),$C$24:$G$24)*BT7*$C$23} -> 5620.3848
B19: Sales VP | C19: ='Sales & Marketing'!D13 -> 2 | K19: Additional Sales Rep | M19: {=_xlfn.XLOOKUP(M$2,_xlfn.ANCHORARRAY($C$21),$C$24:$G$24)*M8*$C$23} -> 0 | N19: {=_xlfn.XLOOKUP(N$2,_xlfn.ANCHORARRAY($C$21),$C$24:$G$24)*N8*$C$23} -> 0 | O19: {=_xlfn.XLOOKUP(O$2,_xlfn.ANCHORARRAY($C$21),$C$24:$G$24)*O8*$C$23} -> 0 | P19: {=_xlfn.XLOOKUP(P$2,_xlfn.ANCHORARRAY($C$21),$C$24:$G$24)*P8*$C$23} -> 0 | Q19: {=_xlfn.XLOOKUP(Q$2,_xlfn.ANCHORARRAY($C$21),$C$24:$G$24)*Q8*$C$23} -> 0 | R19: {=_xlfn.XLOOKUP(R$2,_xlfn.ANCHORARRAY($C$21),$C$24:$G$24)*R8*$C$23} -> 0 | S19: {=_xlfn.XLOOKUP(S$2,_xlfn.ANCHORARRAY($C$21),$C$24:$G$24)*S8*$C$23} -> 0 | T19: {=_xlfn.XLOOKUP(T$2,_xlfn.ANCHORARRAY($C$21),$C$24:$G$24)*T8*$C$23} -> 0 | ... BT19: {=_xlfn.XLOOKUP(BT$2,_xlfn.ANCHORARRAY($C$21),$C$24:$G$24)*BT8*$C$23} -> 866.57194
B20: Senior Sales Rep | C20: ='Sales & Marketing'!D16 -> 3 | K20: Sales Rep | M20: {=_xlfn.XLOOKUP(M$2,_xlfn.ANCHORARRAY($C$21),$C$24:$G$24)*M9*$C$23} -> 0 | N20: {=_xlfn.XLOOKUP(N$2,_xlfn.ANCHORARRAY($C$21),$C$24:$G$24)*N9*$C$23} -> 0 | O20: {=_xlfn.XLOOKUP(O$2,_xlfn.ANCHORARRAY($C$21),$C$24:$G$24)*O9*$C$23} -> 0 | P20: {=_xlfn.XLOOKUP(P$2,_xlfn.ANCHORARRAY($C$21),$C$24:$G$24)*P9*$C$23} -> 0 | Q20: {=_xlfn.XLOOKUP(Q$2,_xlfn.ANCHORARRAY($C$21),$C$24:$G$24)*Q9*$C$23} -> 0 | R20: {=_xlfn.XLOOKUP(R$2,_xlfn.ANCHORARRAY($C$21),$C$24:$G$24)*R9*$C$23} -> 0 | S20: {=_xlfn.XLOOKUP(S$2,_xlfn.ANCHORARRAY($C$21),$C$24:$G$24)*S9*$C$23} -> 0 | T20: {=_xlfn.XLOOKUP(T$2,_xlfn.ANCHORARRAY($C$21),$C$24:$G$24)*T9*$C$23} -> 0 | ... BT20: {=_xlfn.XLOOKUP(BT$2,_xlfn.ANCHORARRAY($C$21),$C$24:$G$24)*BT9*$C$23} -> 5620.3848
C21: {=C2:G2} -> Year 1 | D21: Year 2 | E21: Year 3 | F21: Year 4 | G21: Year 5 | K21: Sales VP | M21: {=_xlfn.XLOOKUP(M$2,_xlfn.ANCHORARRAY($C$21),$C$24:$G$24)*M10*$C$23} -> 0 | N21: {=_xlfn.XLOOKUP(N$2,_xlfn.ANCHORARRAY($C$21),$C$24:$G$24)*N10*$C$23} -> 0 | O21: {=_xlfn.XLOOKUP(O$2,_xlfn.ANCHORARRAY($C$21),$C$24:$G$24)*O10*$C$23} -> 0 | P21: {=_xlfn.XLOOKUP(P$2,_xlfn.ANCHORARRAY($C$21),$C$24:$G$24)*P10*$C$23} -> 0 | Q21: {=_xlfn.XLOOKUP(Q$2,_xlfn.ANCHORARRAY($C$21),$C$24:$G$24)*Q10*$C$23} -> 0 | R21: {=_xlfn.XLOOKUP(R$2,_xlfn.ANCHORARRAY($C$21),$C$24:$G$24)*R10*$C$23} -> 0 | S21: {=_xlfn.XLOOKUP(S$2,_xlfn.ANCHORARRAY($C$21),$C$24:$G$24)*S10*$C$23} -> 0 | T21: {=_xlfn.XLOOKUP(T$2,_xlfn.ANCHORARRAY($C$21),$C$24:$G$24)*T10*$C$23} -> 0 | ... BT21: {=_xlfn.XLOOKUP(BT$2,_xlfn.ANCHORARRAY($C$21),$C$24:$G$24)*BT10*$C$23} -> 5014.5843
B22: Commsions per Sale | K22: Senior Sales Rep | M22: {=_xlfn.XLOOKUP(M$2,_xlfn.ANCHORARRAY($C$21),$C$24:$G$24)*M11*$C$23} -> 0 | N22: {=_xlfn.XLOOKUP(N$2,_xlfn.ANCHORARRAY($C$21),$C$24:$G$24)*N11*$C$23} -> 0 | O22: {=_xlfn.XLOOKUP(O$2,_xlfn.ANCHORARRAY($C$21),$C$24:$G$24)*O11*$C$23} -> 0 | P22: {=_xlfn.XLOOKUP(P$2,_xlfn.ANCHORARRAY($C$21),$C$24:$G$24)*P11*$C$23} -> 0 | Q22: {=_xlfn.XLOOKUP(Q$2,_xlfn.ANCHORARRAY($C$21),$C$24:$G$24)*Q11*$C$23} -> 0 | R22: {=_xlfn.XLOOKUP(R$2,_xlfn.ANCHORARRAY($C$21),$C$24:$G$24)*R11*$C$23} -> 0 | S22: {=_xlfn.XLOOKUP(S$2,_xlfn.ANCHORARRAY($C$21),$C$24:$G$24)*S11*$C$23} -> 0 | T22: {=_xlfn.XLOOKUP(T$2,_xlfn.ANCHORARRAY($C$21),$C$24:$G$24)*T11*$C$23} -> 0 | ... BT22: {=_xlfn.XLOOKUP(BT$2,_xlfn.ANCHORARRAY($C$21),$C$24:$G$24)*BT11*$C$23} -> 2457.0255
B23: 20% of Average Sub Price | C23: 0.2
B24: Avg Sub Price | C24: =AVERAGE(Rev!D11:D17) -> 391.5 | D24: =AVERAGE(Rev!E11:E17) -> 437.5 | E24: =AVERAGE(Rev!F11:F17) -> 513.33333 | F24: =AVERAGE(Rev!G11:G17) -> 558.33333 | G24: =AVERAGE(Rev!H11:H17) -> 633.33333

Sheet Summary P&L
D1: Time | E1: =E3&" "&E4 -> Year 1 Q1 | F1: =F3&" "&F4 -> Year 1 Q2 | G1: =G3&" "&G4 -> Year 1 Q3 | H1: =H3&" "&H4 -> Year 1 Q4 | I1: =I3&" "&I4 -> Year 2 Q1 | J1: =J3&" "&J4 -> Year 2 Q2 | K1: =K3&" "&K4 -> Year 2 Q3 | L1: =L3&" "&L4 -> Year 2 Q4 | ... X1: =X3&" "&X4 -> Year 5 Q4
B2: Quarterly P & L
E3: Year 1 | F3: Year 1 | G3: Year 1 | H3: Year 1 | I3: Year 2 | J3: Year 2 | K3: Year 2 | L3: Year 2 | M3: Year 3 | N3: Year 3 | O3: Year 3 | P3: Year 3 | Q3: Year 4 | R3: Year 4 | S3: Year 4 | T3: Year 4 | U3: Year 5 | V3: Year 5 | W3: Year 5 | X3: Year 5
E4: Q1 | F4: Q2 | G4: Q3 | H4: Q4 | I4: Q1 | J4: Q2 | K4: Q3 | L4: Q4 | M4: Q1 | N4: Q2 | O4: Q3 | P4: Q4 | Q4: Q1 | R4: Q2 | S4: Q3 | T4: Q4 | U4: Q1 | V4: Q2 | W4: Q3 | X4: Q4
D5: Total Revenue | E5: =SUM('P&L'!M9:O9) -> 0 | F5: =SUM('P&L'!P9:R9) -> 0 | G5: =SUM('P&L'!S9:U9) -> 14300 | H5: =SUM('P&L'!V9:X9) -> 22550 | I5: =SUM('P&L'!Y9:AA9) -> 163380 | J5: =SUM('P&L'!AB9:AD9) -> 212990 | K5: =SUM('P&L'!AE9:AG9) -> 270155 | L5: =SUM('P&L'!AH9:AJ9) -> 333605 | M5: =SUM('P&L'!AK9:AM9) -> 662850 | N5: =SUM('P&L'!AN9:AP9) -> 844000 | O5: =SUM('P&L'!AQ9:AS9) -> 1041390 | P5: =SUM('P&L'!AT9:AV9) -> 1289470 | Q5: =SUM('P&L'!AW9:AY9) -> 2069980 | R5: =SUM('P&L'!AZ9:BB9) -> 2561320 | S5: =SUM('P&L'!BC9:BE9) -> 3210020 | T5: =SUM('P&L'!BF9:BH9) -> 3897340 | U5: =SUM('P&L'!BI9:BK9) -> 5692730 | V5: =SUM('P&L'!BL9:BN9) -> 6997420 | W5: =SUM('P&L'!BO9:BQ9) -> 8491070 | X5: =SUM('P&L'!BR9:BT9) -> 10243280
D6: COGS | E6: =SUM('P&L'!M23:O23) -> 0 | F6: =SUM('P&L'!P23:R23) -> 1000 | G6: =SUM('P&L'!S23:U23) -> 3246.5 | H6: =SUM('P&L'!V23:X23) -> 3589 | I6: =SUM('P&L'!Y23:AA23) -> 9092.5 | J6: =SUM('P&L'!AB23:AD23) -> 10427.5 | K6: =SUM('P&L'!AE23:AG23) -> 11880 | L6: =SUM('P&L'!AH23:AJ23) -> 13611.25 | M6: =SUM('P&L'!AK23:AM23) -> 27027.5 | N6: =SUM('P&L'!AN23:AP23) -> 32567.25 | O6: =SUM('P&L'!AQ23:AS23) -> 38924 | P6: =SUM('P&L'!AT23:AV23) -> 46425 | Q6: =SUM('P&L'!AW23:AY23) -> 82431.875 | R6: =SUM('P&L'!AZ23:BB23) -> 104172.5 | S6: =SUM('P&L'!BC23:BE23) -> 129909.38 | T6: =SUM('P&L'!BF23:BH23) -> 159240.62 | U6: =SUM('P&L'!BI23:BK23) -> 257402.5 | V6: =SUM('P&L'!BL23:BN23) -> 319466.25 | W6: =SUM('P&L'!BO23:BQ23) -> 391228.75 | X6: =SUM('P&L'!BR23:BT23) -> 474646.25
C7: Gross Profit | E7: =E5-E6 -> 0 | F7: =SUM('P&L'!P25:R25) -> -1000 | G7: =SUM('P&L'!S25:U25) -> 11053.5 | H7: =SUM('P&L'!V25:X25) -> 18961 | I7: =SUM('P&L'!Y25:AA25) -> 154287.5 | J7: =SUM('P&L'!AB25:AD25) -> 202562.5 | K7: =SUM('P&L'!AE25:AG25) -> 258275 | L7: =SUM('P&L'!AH25:AJ25) -> 319993.75 | M7: =SUM('P&L'!AK25:AM25) -> 635822.5 | N7: =SUM('P&L'!AN25:AP25) -> 811432.75 | O7: =SUM('P&L'!AQ25:AS25) -> 1002466 | P7: =SUM('P&L'!AT25:AV25) -> 1243045 | Q7: =SUM('P&L'!AW25:AY25) -> 1987548.1 | R7: =SUM('P&L'!AZ25:BB25) -> 2457147.5 | S7: =SUM('P&L'!BC25:BE25) -> 3080110.6 | T7: =SUM('P&L'!BF25:BH25) -> 3738099.4 | U7: =SUM('P&L'!BI25:BK25) -> 5435327.5 | V7: =SUM('P&L'!BL25:BN25) -> 6677953.8 | W7: =SUM('P&L'!BO25:BQ25) -> 8099841.2 | X7: =SUM('P&L'!BR25:BT25) -> 9768633.8
C8: Operating Expenses
D9: R&D | E9: =SUM('P&L'!M28:O28) -> 49550 | F9: =SUM('P&L'!P28:R28) -> 107616.67 | G9: =SUM('P&L'!S28:U28) -> 136650 | H9: =SUM('P&L'!V28:X28) -> 136650 | I9: =SUM('P&L'!Y28:AA28) -> 202189.17 | J9: =SUM('P&L'!AB28:AD28) -> 291119.17 | K9: =SUM('P&L'!AE28:AG28) -> 359062.5 | L9: =SUM('P&L'!AH28:AJ28) -> 359062.5 | M9: =SUM('P&L'!AK28:AM28) -> 410377.29 | N9: =SUM('P&L'!AN28:AP28) -> 499670.63 | O9: =SUM('P&L'!AQ28:AS28) -> 587358.96 | P9: =SUM('P&L'!AT28:AV28) -> 650835.63 | Q9: =SUM('P&L'!AW28:AY28) -> 773157.41 | R9: =SUM('P&L'!AZ28:BB28) -> 802190.74 | S9: =SUM('P&L'!BC28:BE28) -> 910720.74 | T9: =SUM('P&L'!BF28:BH28) -> 984930.74 | U9: =SUM('P&L'!BI28:BK28) -> 1044634.8 | V9: =SUM('P&L'!BL28:BN28) -> 1044634.8 | W9: =SUM('P&L'!BO28:BQ28) -> 1044634.8 | X9: =SUM('P&L'!BR28:BT28) -> 1044634.8
D10: Marketing | E10: =SUM('P&L'!M29:O29) -> 38250 | F10: =SUM('P&L'!P29:R29) -> 38250 | G10: =SUM('P&L'!S29:U29) -> 38250 | H10: =SUM('P&L'!V29:X29) -> 38250 | I10: =SUM('P&L'!Y29:AA29) -> 67575 | J10: =SUM('P&L'!AB29:AD29) -> 67575 | K10: =SUM('P&L'!AE29:AG29) -> 67575 | L10: =SUM('P&L'!AH29:AJ29) -> 67575 | M10: =SUM('P&L'!AK29:AM29) -> 85450 | N10: =SUM('P&L'!AN29:AP29) -> 85450 | O10: =SUM('P&L'!AQ29:AS29) -> 85450 | P10: =SUM('P&L'!AT29:AV29) -> 85450 | Q10: =SUM('P&L'!AW29:AY29) -> 101325 | R10: =SUM('P&L'!AZ29:BB29) -> 101325 | S10: =SUM('P&L'!BC29:BE29) -> 101325 | T10: =SUM('P&L'!BF29:BH29) -> 101325 | U10: =SUM('P&L'!BI29:BK29) -> 115950 | V10: =SUM('P&L'!BL29:BN29) -> 115950 | W10: =SUM('P&L'!BO29:BQ29) -> 115950 | X10: =SUM('P&L'!BR29:BT29) -> 115950
D11: G&A | E11: =SUM('P&L'!M30:O30) -> 296225 | F11: =SUM('P&L'!P30:R30) -> 296225 | G11: =SUM('P&L'!S30:U30) -> 300698.33 | H11: =SUM('P&L'!V30:X30) -> 313228.33 | I11: =SUM('P&L'!Y30:AA30) -> 400973.33 | J11: =SUM('P&L'!AB30:AD30) -> 493015 | K11: =SUM('P&L'!AE30:AG30) -> 495265 | L11: =SUM('P&L'!AH30:AJ30) -> 508765 | M11: =SUM('P&L'!AK30:AM30) -> 566160 | N11: =SUM('P&L'!AN30:AP30) -> 576160 | O11: =SUM('P&L'!AQ30:AS30) -> 581160 | P11: =SUM('P&L'!AT30:AV30) -> 581160 | Q11: =SUM('P&L'!AW30:AY30) -> 751635 | R11: =SUM('P&L'!AZ30:BB30) -> 710635 | S11: =SUM('P&L'!BC30:BE30) -> 682635 | T11: =SUM('P&L'!BF30:BH30) -> 682635 | U11: =SUM('P&L'!BI30:BK30) -> 682635 | V11: =SUM('P&L'!BL30:BN30) -> 682635 | W11: =SUM('P&L'!BO30:BQ30) -> 682635 | X11: =SUM('P&L'!BR30:BT30) -> 682635
D12: Sales | E12: =SUM('P&L'!M31:O31) -> 1500 | F12: =SUM('P&L'!P31:R31) -> 1500 | G12: =SUM('P&L'!S31:U31) -> 1500 | H12: =SUM('P&L'!V31:X31) -> 1500 | I12: =SUM('P&L'!Y31:AA31) -> 68013.75 | J12: =SUM('P&L'!AB31:AD31) -> 68762.206 | K12: =SUM('P&L'!AE31:AG31) -> 69049.826 | L12: =SUM('P&L'!AH31:AJ31) -> 69382.781 | M12: =SUM('P&L'!AK31:AM31) -> 99162.073 | N12: =SUM('P&L'!AN31:AP31) -> 100849.25 | O12: =SUM('P&L'!AQ31:AS31) -> 101842.66 | P12: =SUM('P&L'!AT31:AV31) -> 102992.65 | Q12: =SUM('P&L'!AW31:AY31) -> 159654.01 | R12: =SUM('P&L'!AZ31:BB31) -> 164004.28 | S12: =SUM('P&L'!BC31:BE31) -> 166867.82 | T12: =SUM('P&L'!BF31:BH31) -> 170182.73 | U12: =SUM('P&L'!BI31:BK31) -> 207139.57 | V12: =SUM('P&L'!BL31:BN31) -> 216665.48 | W12: =SUM('P&L'!BO31:BQ31) -> 223761.54 | X12: =SUM('P&L'!BR31:BT31) -> 231976.11
D13: Total Operating Expense | E13: =SUM(E9:E11) -> 384025 | F13: =SUM('P&L'!P33:R33) -> 443591.67 | G13: =SUM('P&L'!S33:U33) -> 477098.33 | H13: =SUM('P&L'!V33:X33) -> 489628.33 | I13: =SUM('P&L'!Y33:AA33) -> 738751.25 | J13: =SUM('P&L'!AB33:AD33) -> 920471.37 | K13: =SUM('P&L'!AE33:AG33) -> 990952.33 | L13: =SUM('P&L'!AH33:AJ33) -> 1004785.3 | M13: =SUM('P&L'!AK33:AM33) -> 1161149.4 | N13: =SUM('P&L'!AN33:AP33) -> 1262129.9 | O13: =SUM('P&L'!AQ33:AS33) -> 1355811.6 | P13: =SUM('P&L'!AT33:AV33) -> 1420438.3 | Q13: =SUM('P&L'!AW33:AY33) -> 1785771.4 | R13: =SUM('P&L'!AZ33:BB33) -> 1778155 | S13: =SUM('P&L'!BC33:BE33) -> 1861548.6 | T13: =SUM('P&L'!BF33:BH33) -> 1939073.5 | U13: =SUM('P&L'!BI33:BK33) -> 2050359.3 | V13: =SUM('P&L'!BL33:BN33) -> 2059885.3 | W13: =SUM('P&L'!BO33:BQ33) -> 2066981.3 | X13: =SUM('P&L'!BR33:BT33) -> 2075195.9
C14: Operating Income | E14: =E7-E13 -> -384025 | F14: =SUM('P&L'!P36:R36) -> -444591.67 | G14: =SUM('P&L'!S36:U36) -> -466044.83 | H14: =SUM('P&L'!V36:X36) -> -470667.33 | I14: =SUM('P&L'!Y36:AA36) -> -584463.75 | J14: =SUM('P&L'!AB36:AD36) -> -717908.87 | K14: =SUM('P&L'!AE36:AG36) -> -732677.33 | L14: =SUM('P&L'!AH36:AJ36) -> -684791.53 | M14: =SUM('P&L'!AK36:AM36) -> -525326.86 | N14: =SUM('P&L'!AN36:AP36) -> -450697.12 | O14: =SUM('P&L'!AQ36:AS36) -> -353345.61 | P14: =SUM('P&L'!AT36:AV36) -> -177393.28 | Q14: =SUM('P&L'!AW36:AY36) -> 201776.71 | R14: =SUM('P&L'!AZ36:BB36) -> 678992.48 | S14: =SUM('P&L'!BC36:BE36) -> 1218562.1 | T14: =SUM('P&L'!BF36:BH36) -> 1799025.9 | U14: =SUM('P&L'!BI36:BK36) -> 3384968.2 | V14: =SUM('P&L'!BL36:BN36) -> 4618068.5 | W14: =SUM('P&L'!BO36:BQ36) -> 6032859.9 | X14: =SUM('P&L'!BR36:BT36) -> 7693437.9
C16: Depreciation | E16: =SUM('P&L'!M38:O38) -> 1400 | F16: =SUM('P&L'!P38:R38) -> 1400 | G16: =SUM('P&L'!S38:U38) -> 1400 | H16: =SUM('P&L'!V38:X38) -> 1400 | I16: =SUM('P&L'!Y38:AA38) -> 2150 | J16: =SUM('P&L'!AB38:AD38) -> 2150 | K16: =SUM('P&L'!AE38:AG38) -> 2150 | L16: =SUM('P&L'!AH38:AJ38) -> 2150 | M16: =SUM('P&L'!AK38:AM38) -> 3350 | N16: =SUM('P&L'!AN38:AP38) -> 3350 | O16: =SUM('P&L'!AQ38:AS38) -> 3350 | P16: =SUM('P&L'!AT38:AV38) -> 3350 | Q16: =SUM('P&L'!AW38:AY38) -> 4400 | R16: =SUM('P&L'!AZ38:BB38) -> 4400 | S16: =SUM('P&L'!BC38:BE38) -> 4400 | T16: =SUM('P&L'!BF38:BH38) -> 4400 | U16: =SUM('P&L'!BI38:BK38) -> 4400 | V16: =SUM('P&L'!BL38:BN38) -> 4400 | W16: =SUM('P&L'!BO38:BQ38) -> 4400 | X16: =SUM('P&L'!BR38:BT38) -> 4400
C17: Interest Exp | E17: =SUM('P&L'!M39:O39) -> 4931.8001 | F17: =SUM('P&L'!P39:R39) -> 4724.9171 | G17: =SUM('P&L'!S39:U39) -> 4513.8688 | H17: =SUM('P&L'!V39:X39) -> 4298.5713 | I17: =SUM('P&L'!Y39:AA39) -> 4078.9391 | J17: =SUM('P&L'!AB39:AD39) -> 3854.8849 | K17: =SUM('P&L'!AE39:AG39) -> 3626.3196 | L17: =SUM('P&L'!AH39:AJ39) -> 3393.1525 | M17: =SUM('P&L'!AK39:AM39) -> 3155.291 | N17: =SUM('P&L'!AN39:AP39) -> 2912.6404 | O17: =SUM('P&L'!AQ39:AS39) -> 2665.1043 | P17: =SUM('P&L'!AT39:AV39) -> 2412.5845 | Q17: =SUM('P&L'!AW39:AY39) -> 2154.9805 | R17: =SUM('P&L'!AZ39:BB39) -> 1892.19 | S17: =SUM('P&L'!BC39:BE39) -> 1624.1086 | T17: =SUM('P&L'!BF39:BH39) -> 1350.6298 | U17: =SUM('P&L'!BI39:BK39) -> 1071.6448 | V17: =SUM('P&L'!BL39:BN39) -> 787.04283 | W17: =SUM('P&L'!BO39:BQ39) -> 496.7108 | X17: =SUM('P&L'!BR39:BT39) -> 200.53333
C18: Pre tax income | E18: =SUM('P&L'!M41:O41) -> -391856.8 | F18: =SUM('P&L'!P41:R41) -> -450716.58 | G18: =SUM('P&L'!S41:U41) -> -471958.7 | H18: =SUM('P&L'!V41:X41) -> -476365.9 | I18: =SUM('P&L'!Y41:AA41) -> -590692.69 | J18: =SUM('P&L'!AB41:AD41) -> -723913.76 | K18: =SUM('P&L'!AE41:AG41) -> -738453.65 | L18: =SUM('P&L'!AH41:AJ41) -> -690334.68 | M18: =SUM('P&L'!AK41:AM41) -> -531832.16 | N18: =SUM('P&L'!AN41:AP41) -> -456959.76 | O18: =SUM('P&L'!AQ41:AS41) -> -359360.72 | P18: =SUM('P&L'!AT41:AV41) -> -183155.86 | Q18: =SUM('P&L'!AW41:AY41) -> 195221.73 | R18: =SUM('P&L'!AZ41:BB41) -> 672700.29 | S18: =SUM('P&L'!BC41:BE41) -> 1212538 | T18: =SUM('P&L'!BF41:BH41) -> 1793275.3 | U18: =SUM('P&L'!BI41:BK41) -> 3379496.5 | V18: =SUM('P&L'!BL41:BN41) -> 4612881.5 | W18: =SUM('P&L'!BO41:BQ41) -> 6027963.2 | X18: =SUM('P&L'!BR41:BT41) -> 7688837.3
C19: Taxes @20% | E19: =SUM('P&L'!M42:O42) -> 0 | F19: =SUM('P&L'!P42:R42) -> 0 | G19: =SUM('P&L'!S42:U42) -> 0 | H19: =SUM('P&L'!V42:X42) -> 0 | I19: =SUM('P&L'!Y42:AA42) -> 0 | J19: =SUM('P&L'!AB42:AD42) -> 0 | K19: =SUM('P&L'!AE42:AG42) -> 0 | L19: =SUM('P&L'!AH42:AJ42) -> 0 | M19: =SUM('P&L'!AK42:AM42) -> 0 | N19: =SUM('P&L'!AN42:AP42) -> 0 | O19: =SUM('P&L'!AQ42:AS42) -> 0 | P19: =SUM('P&L'!AT42:AV42) -> 0 | Q19: =SUM('P&L'!AW42:AY42) -> 39044.345 | R19: =SUM('P&L'!AZ42:BB42) -> 134540.06 | S19: =SUM('P&L'!BC42:BE42) -> 242507.59 | T19: =SUM('P&L'!BF42:BH42) -> 358655.06 | U19: =SUM('P&L'!BI42:BK42) -> 675899.3 | V19: =SUM('P&L'!BL42:BN42) -> 922576.29 | W19: =SUM('P&L'!BO42:BQ42) -> 1205592.6 | X19: =SUM('P&L'!BR42:BT42) -> 1537767.5
C20: Net Income | E20: =SUM('P&L'!M44:O44) -> -391856.8 | F20: =SUM('P&L'!P44:R44) -> -450716.58 | G20: =SUM('P&L'!S44:U44) -> -471958.7 | H20: =SUM('P&L'!V44:X44) -> -476365.9 | I20: =SUM('P&L'!Y44:AA44) -> -590692.69 | J20: =SUM('P&L'!AB44:AD44) -> -723913.76 | K20: =SUM('P&L'!AE44:AG44) -> -738453.65 | L20: =SUM('P&L'!AH44:AJ44) -> -690334.68 | M20: =SUM('P&L'!AK44:AM44) -> -531832.16 | N20: =SUM('P&L'!AN44:AP44) -> -456959.76 | O20: =SUM('P&L'!AQ44:AS44) -> -359360.72 | P20: =SUM('P&L'!AT44:AV44) -> -183155.86 | Q20: =SUM('P&L'!AW44:AY44) -> 156177.38 | R20: =SUM('P&L'!AZ44:BB44) -> 538160.23 | S20: =SUM('P&L'!BC44:BE44) -> 970030.36 | T20: =SUM('P&L'!BF44:BH44) -> 1434620.2 | U20: =SUM('P&L'!BI44:BK44) -> 2703597.2 | V20: =SUM('P&L'!BL44:BN44) -> 3690305.2 | W20: =SUM('P&L'!BO44:BQ44) -> 4822370.6 | X20: =SUM('P&L'!BR44:BT44) -> 6151069.9
C21: Retained Earnings | E21: =D21+E20 -> -391856.8 | F21: =E21+F20 -> -842573.38 | G21: =F21+G20 -> -1314532.1 | H21: =G21+H20 -> -1790898 | I21: =H21+I20 -> -2381590.7 | J21: =I21+J20 -> -3105504.4 | K21: =J21+K20 -> -3843958.1 | L21: =K21+L20 -> -4534292.8 | ... X21: =W21+X20 -> 14400730
B23: Quarterly Cash Flow
B25: Net Income Method
C26: Beginning Cash | E26: 0 | F26: =E36 -> 407517.7 | G26: =F36 -> 33968.742 | H26: =G36 -> -361361.39 | I26: =H36 -> 1738833 | J26: =I36 -> 1207295.3 | K26: =J36 -> 559631.57 | L26: =K36 -> -132139.9 | M26: =L36 -> 8166599.6 | ... X26: =W36 -> 20631423
C27: Net Income | E27: =SUM('P&L'!M52:O52) -> -391856.8 | F27: =SUM('P&L'!P52:R52) -> -450716.58 | G27: =SUM('P&L'!S52:U52) -> -471958.7 | H27: =SUM('P&L'!V52:X52) -> -476365.9 | I27: =SUM('P&L'!Y52:AA52) -> -590692.69 | J27: =SUM('P&L'!AB52:AD52) -> -723913.76 | K27: =SUM('P&L'!AE52:AG52) -> -738453.65 | L27: =SUM('P&L'!AH52:AJ52) -> -690334.68 | M27: =SUM('P&L'!AK52:AM52) -> -531832.16 | N27: =SUM('P&L'!AN52:AP52) -> -456959.76 | O27: =SUM('P&L'!AQ52:AS52) -> -359360.72 | P27: =SUM('P&L'!AT52:AV52) -> -183155.86 | Q27: =SUM('P&L'!AW52:AY52) -> 156177.38 | R27: =SUM('P&L'!AZ52:BB52) -> 538160.23 | S27: =SUM('P&L'!BC52:BE52) -> 970030.36 | T27: =SUM('P&L'!BF52:BH52) -> 1434620.2 | U27: =SUM('P&L'!BI52:BK52) -> 2703597.2 | V27: =SUM('P&L'!BL52:BN52) -> 3690305.2 | W27: =SUM('P&L'!BO52:BQ52) -> 4822370.6 | X27: =SUM('P&L'!BR52:BT52) -> 6151069.9
C28: Equity Investment (+) | E28: =SUM('P&L'!M53:O53) -> 500000 | F28: =SUM('P&L'!P53:R53) -> 0 | G28: =SUM('P&L'!S53:U53) -> 0 | H28: =SUM('P&L'!V53:X53) -> 2500000 | I28: =SUM('P&L'!Y53:AA53) -> 0 | J28: =SUM('P&L'!AB53:AD53) -> 0 | K28: =SUM('P&L'!AE53:AG53) -> 0 | L28: =SUM('P&L'!AH53:AJ53) -> 9000000 | M28: =SUM('P&L'!AK53:AM53) -> 0 | N28: =SUM('P&L'!AN53:AP53) -> 0 | O28: =SUM('P&L'!AQ53:AS53) -> 0 | P28: =SUM('P&L'!AT53:AV53) -> 0 | Q28: =SUM('P&L'!AW53:AY53) -> 0 | R28: =SUM('P&L'!AZ53:BB53) -> 0 | S28: =SUM('P&L'!BC53:BE53) -> 0 | T28: =SUM('P&L'!BF53:BH53) -> 0 | U28: =SUM('P&L'!BI53:BK53) -> 0 | V28: =SUM('P&L'!BL53:BN53) -> 0 | W28: =SUM('P&L'!BO53:BQ53) -> 0 | X28: =SUM('P&L'!BR53:BT53) -> 0
C29: Change in A/R (+/-) | E29: =SUM('P&L'!M54:O54) -> 0 | F29: =SUM('P&L'!P54:R54) -> 0 | G29: =SUM('P&L'!S54:U54) -> -328 | H29: =SUM('P&L'!V54:X54) -> -181 | I29: =SUM('P&L'!Y54:AA54) -> -3116.6 | J29: =SUM('P&L'!AB54:AD54) -> -797.6 | K29: =SUM('P&L'!AE54:AG54) -> -1386.85 | L29: =SUM('P&L'!AH54:AJ54) -> -1261.7 | M29: =SUM('P&L'!AK54:AM54) -> -6907.25 | N29: =SUM('P&L'!AN54:AP54) -> -4023.1 | O29: =SUM('P&L'!AQ54:AS54) -> -4027 | P29: =SUM('P&L'!AT54:AV54) -> -5386.8 | Q29: =SUM('P&L'!AW54:AY54) -> -16963 | R29: =SUM('P&L'!AZ54:BB54) -> -9827.2 | S29: =SUM('P&L'!BC54:BE54) -> -13334.3 | T29: =SUM('P&L'!BF54:BH54) -> -14667.1 | U29: =SUM('P&L'!BI54:BK54) -> -38411.7 | V29: =SUM('P&L'!BL54:BN54) -> -26957.8 | W29: =SUM('P&L'!BO54:BQ54) -> -31066.6 | X29: =SUM('P&L'!BR54:BT54) -> -36696.1
C30: Capital Expenditures (-) | E30: =SUM('P&L'!M55:O55) -> -28000 | F30: =SUM('P&L'!P55:R55) -> 0 | G30: =SUM('P&L'!S55:U55) -> 0 | H30: =SUM('P&L'!V55:X55) -> 0 | I30: =SUM('P&L'!Y55:AA55) -> -15000 | J30: =SUM('P&L'!AB55:AD55) -> 0 | K30: =SUM('P&L'!AE55:AG55) -> 0 | L30: =SUM('P&L'!AH55:AJ55) -> 0 | M30: =SUM('P&L'!AK55:AM55) -> -24000 | N30: =SUM('P&L'!AN55:AP55) -> 0 | O30: =SUM('P&L'!AQ55:AS55) -> 0 | P30: =SUM('P&L'!AT55:AV55) -> 0 | Q30: =SUM('P&L'!AW55:AY55) -> -21000 | R30: =SUM('P&L'!AZ55:BB55) -> 0 | S30: =SUM('P&L'!BC55:BE55) -> 0 | T30: =SUM('P&L'!BF55:BH55) -> 0 | U30: =SUM('P&L'!BI55:BK55) -> 0 | V30: =SUM('P&L'!BL55:BN55) -> 0 | W30: =SUM('P&L'!BO55:BQ55) -> 0 | X30: =SUM('P&L'!BR55:BT55) -> 0
C31: Borrowings (+) | E31: =SUM('P&L'!M56:O56) -> 250000 | F31: =SUM('P&L'!P56:R56) -> 0 | G31: =SUM('P&L'!S56:U56) -> 0 | H31: =SUM('P&L'!V56:X56) -> 0 | I31: =SUM('P&L'!Y56:AA56) -> 0 | J31: =SUM('P&L'!AB56:AD56) -> 0 | K31: =SUM('P&L'!AE56:AG56) -> 0 | L31: =SUM('P&L'!AH56:AJ56) -> 0 | M31: =SUM('P&L'!AK56:AM56) -> 0 | N31: =SUM('P&L'!AN56:AP56) -> 0 | O31: =SUM('P&L'!AQ56:AS56) -> 0 | P31: =SUM('P&L'!AT56:AV56) -> 0 | Q31: =SUM('P&L'!AW56:AY56) -> 0 | R31: =SUM('P&L'!AZ56:BB56) -> 0 | S31: =SUM('P&L'!BC56:BE56) -> 0 | T31: =SUM('P&L'!BF56:BH56) -> 0 | U31: =SUM('P&L'!BI56:BK56) -> 0 | V31: =SUM('P&L'!BL56:BN56) -> 0 | W31: =SUM('P&L'!BO56:BQ56) -> 0 | X31: =SUM('P&L'!BR56:BT56) -> 0
C32: COGS (Related to Inventory) (+) | E32: =SUM('P&L'!M57:O57) -> 0 | F32: =SUM('P&L'!P57:R57) -> 0 | G32: =SUM('P&L'!S57:U57) -> 0 | H32: =SUM('P&L'!V57:X57) -> 0 | I32: =SUM('P&L'!Y57:AA57) -> 0 | J32: =SUM('P&L'!AB57:AD57) -> 0 | K32: =SUM('P&L'!AE57:AG57) -> 0 | L32: =SUM('P&L'!AH57:AJ57) -> 0 | M32: =SUM('P&L'!AK57:AM57) -> 0 | N32: =SUM('P&L'!AN57:AP57) -> 0 | O32: =SUM('P&L'!AQ57:AS57) -> 0 | P32: =SUM('P&L'!AT57:AV57) -> 0 | Q32: =SUM('P&L'!AW57:AY57) -> 0 | R32: =SUM('P&L'!AZ57:BB57) -> 0 | S32: =SUM('P&L'!BC57:BE57) -> 0 | T32: =SUM('P&L'!BF57:BH57) -> 0 | U32: =SUM('P&L'!BI57:BK57) -> 0 | V32: =SUM('P&L'!BL57:BN57) -> 0 | W32: =SUM('P&L'!BO57:BQ57) -> 0 | X32: =SUM('P&L'!BR57:BT57) -> 0
